Workbook

Sheet Control-Sheet
B3: 1. Cuplane-interface | O3: NR | Q3: LTE
G4: 삭제 금지 | N4: BW | O4: KHZ_15 | P4: KHZ_30 | Q4: KHZ_15
C5: name | D5: 1000 | E5: VLAN NAME | G5: <exponent>4</exponent> | K5: <!-- | N5: 5 | O5: 25 | P5: 11 | Q5: 25
C6: Base-interface | D6: sys | E6: 고정 | G6: <compression-method>BLOCK_FLOATING_POINT</compression-method> | K6: --> | N6: 10 | O6: 52 | P6: 24 | Q6: 50
C7: vlan id | D7: 1000 | N7: 15 | O7: 79 | P7: 38 | Q7: 75
C8: ORU mac-address | D8: dc:c1:01:00:05:05 | E8: nDLPU MAC | N8: 20 | O8: 106 | P8: 51 | Q8: 100
N9: 25 | O9: 216 | P9: 65
N10: 30 | O10: 270 | P10: 78
B11: 2. Processing element | N11: 40 | P11: 106
N12: 50 | P12: 133
C13: name | D13: ru-pe.0 | E13: oran player | N13: 60 | P13: 162
C14: ODU mac-address | D14: 00:11:22:33:44:55 | E14: 변경 가능 고정 사용 | N14: 80 | P14: 217
N15: 90 | P15: 245
N16: 100 | P16: 273
R17: 0.509
R18: Tc = 1 / (480kHz · 4096) = 0.509 ns
B19: 3. PDSCH | R19: TC =~ 0.5 ns = 1/1.96608GHz | W19: <exponent>4<exponent>
R20: 10000
C21: end-point | G21: link | K21: array-carrier | R21: 100 | S21: 6.81
C22: name | D22: scs | E22: number-of-prb | F22: eaxc-id | G22: name | H22: processing-element | I22: rx-array-carrier | J22: low-level-rx-endpoint | K22: name | L22: iq-bitwidth | M22: compression | N22: Center-FREQ | O22: Channel-BW | P22: type | Q22: gain | R22: T-da-offset
A23: ON | B23: C0 | C23: llte_0_0_0_1_0_0 | D23: KHZ_15 | E23: 106 | F23: 2 | G23: llte_0_0_0_1_0_0 | H23: ru-pe.0 | I23: tac_0_0_0_1 | J23: llte_0_0_0_1_0_0 | K23: tac_0_0_0_1 | L23: 16 | M23: no comp | N23: 3415 | O23: 10 | P23: NR | Q23: 7 | T23: 6.8 | V23: =DEC2HEX(F23) -> 2 | W23: 7
A24: ON | B24: C1 | C24: llte_0_0_1_1_0_0 | D24: KHZ_15 | E24: 106 | F24: 3 | G24: llte_0_0_1_1_0_0 | H24: ru-pe.0 | I24: tac_0_0_1_1 | J24: llte_0_0_1_1_0_0 | K24: tac_0_0_1_1 | L24: 16 | M24: no comp | N24: 3445 | O24: 10 | P24: NR | Q24: 7 | T24: 4.2 | V24: =DEC2HEX(F24) -> 3 | W24: =W23 -> 7
A25: ON | B25: C2 | C25: llte_0_0_0_2_0_0 | D25: KHZ_15 | E25: 106 | F25: 4 | G25: llte_0_0_0_2_0_0 | H25: ru-pe.0 | I25: tac_0_0_0_2 | J25: llte_0_0_0_2_0_0 | K25: tac_0_0_0_2 | L25: 16 | M25: no comp | N25: 3415 | O25: 10 | P25: NR | Q25: 7 | V25: =DEC2HEX(F25) -> 4 | W25: =W24 -> 7
A26: ON | B26: C3 | C26: llte_0_0_1_2_0_0 | D26: KHZ_15 | E26: 106 | F26: 5 | G26: llte_0_0_1_2_0_0 | H26: ru-pe.0 | I26: tac_0_0_1_2 | J26: llte_0_0_1_2_0_0 | K26: tac_0_0_1_2 | L26: 16 | M26: no comp | N26: 3445 | O26: 10 | P26: NR | Q26: 7 | V26: =DEC2HEX(F26) -> 5 | W26: =W25 -> 7
A27: ON | B27: C4 | C27: llte_0_0_0_3_0_0 | D27: KHZ_15 | E27: 106 | F27: 6 | G27: llte_0_0_0_3_0_0 | H27: ru-pe.0 | I27: tac_0_0_0_3 | J27: llte_0_0_0_3_0_0 | K27: tac_0_0_0_3 | L27: 16 | M27: no comp | N27: 3415 | O27: 10 | P27: NR | Q27: 7 | V27: =DEC2HEX(F27) -> 6 | W27: =W26 -> 7 | AH27: UL Center
A28: ON | B28: C5 | C28: llte_0_0_1_3_0_0 | D28: KHZ_15 | E28: 106 | F28: 7 | G28: llte_0_0_1_3_0_0 | H28: ru-pe.0 | I28: tac_0_0_1_3 | J28: llte_0_0_1_3_0_0 | K28: tac_0_0_1_3 | L28: 16 | M28: no comp | N28: 3445 | O28: 10 | P28: NR | Q28: 7 | V28: =DEC2HEX(F28) -> 7 | W28: =W27 -> 7 | AH28: 3900
A29: ON | B29: C6 | C29: llte_0_0_0_4_0_0 | D29: KHZ_15 | E29: 106 | F29: 8 | G29: llte_0_0_0_4_0_0 | H29: ru-pe.0 | I29: tac_0_0_0_4 | J29: llte_0_0_0_4_0_0 | K29: tac_0_0_0_4 | L29: 16 | M29: no comp | N29: 3415 | O29: 10 | P29: NR | Q29: 7 | V29: =DEC2HEX(F29) -> 8 | W29: =W28 -> 7
A30: ON | B30: C7 | C30: llte_0_0_1_4_0_0 | D30: KHZ_15 | E30: 106 | F30: 9 | G30: llte_0_0_1_4_0_0 | H30: ru-pe.0 | I30: tac_0_0_1_4 | J30: llte_0_0_1_4_0_0 | K30: tac_0_0_1_4 | L30: 16 | M30: no comp | N30: 3445 | O30: 10 | P30: NR | Q30: 7 | V30: =DEC2HEX(F30) -> 9 | W30: =W29 -> 7
C31: 고정 | F31: dec (oran은 hex로) | G31: 가능하나 고정 | H31: 가능하나 고정 | I31: 가능하나 고정 | J31: =C31 -> 고정 | K31: 가능하나 고정
B32: 4. PUSCH | S32: TC =~ 0.5 ns = 1/1.96608GHz
R33: =R36*R17 -> 13030.4 | S33: =S34*1000 -> 100000 | V33: =R34 -> 13.0304 | W33: =V33/1000 -> 0.0130304 | X33: 10 | Y33: =X33-W33 -> 9.9869696
C34: end-point | H34: link | N34: array-carrier | R34: =R33/1000 -> 13.0304 | S34: 100 | T34: 1.89 | U34: 4.09 | V34: =S34+R34 -> 113.0304 | W34: =V34/1000 -> 0.1130304 | X34: 10 | Y34: =X34-W34 -> 9.8869696
C35: name | D35: scs | E35: number-of-prb | F35: ul-fft-sampling-offset | G35: eaxc-id | H35: name | I35: processing-element | J35: rx-array-carrier | K35: low-level-rx-endpoint | L35: iq-bitwidth | M35: compression | N35: name | O35: Center-FREQ | P35: Channel-BW | Q35: type | R35: n-ta-offset | S35: T-au-offset | T35: Gain-Correction
B36: C0 | C36: llre_0_0_0_1_0_0 | D36: KHZ_15 | E36: 106 | F36: 0 | G36: 18 | H36: llre_0_0_0_1_0_0 | I36: ru-pe.0 | J36: rac_0_0_0_1 | K36: llre_0_0_0_1_0_0 | L36: 16 | M36: no comp | N36: rac_0_0_0_1 | O36: 3415 | P36: 10 | Q36: NR | R36: 25600 | T36: 0
B37: C1 | C37: llre_0_0_1_1_0_0 | D37: KHZ_15 | E37: 106 | F37: 0 | G37: 19 | H37: llre_0_0_1_1_0_0 | I37: ru-pe.0 | J37: rac_0_0_1_1 | K37: llre_0_0_1_1_0_0 | L37: 16 | M37: no comp | N37: rac_0_0_1_1 | O37: 3445 | P37: 10 | Q37: NR | R37: 25600 | T37: 0
B38: C2 | C38: llre_0_0_0_2_0_0 | D38: KHZ_15 | E38: 106 | F38: 0 | G38: 20 | H38: llre_0_0_0_2_0_0 | I38: ru-pe.0 | J38: rac_0_0_0_2 | K38: llre_0_0_0_2_0_0 | L38: 16 | M38: no comp | N38: rac_0_0_0_2 | O38: 3415 | P38: 10 | Q38: NR | R38: 25600 | T38: 0
B39: C3 | C39: llre_0_0_1_2_0_0 | D39: KHZ_15 | E39: 106 | F39: 0 | G39: 21 | H39: llre_0_0_1_2_0_0 | I39: ru-pe.0 | J39: rac_0_0_1_2 | K39: llre_0_0_1_2_0_0 | L39: 16 | M39: no comp | N39: rac_0_0_1_2 | O39: 3445 | P39: 10 | Q39: NR | R39: 25600 | T39: 0
B40: C4 | C40: llre_0_0_0_3_0_0 | D40: KHZ_15 | E40: 106 | F40: 0 | G40: 22 | H40: llre_0_0_0_3_0_0 | I40: ru-pe.0 | J40: rac_0_0_0_3 | K40: llre_0_0_0_3_0_0 | L40: 16 | M40: no comp | N40: rac_0_0_0_3 | O40: 3415 | P40: 10 | Q40: NR | R40: 25600 | T40: 0
B41: C5 | C41: llre_0_0_1_3_0_0 | D41: KHZ_15 | E41: 106 | F41: 0 | G41: 23 | H41: llre_0_0_1_3_0_0 | I41: ru-pe.0 | J41: rac_0_0_1_3 | K41: llre_0_0_1_3_0_0 | L41: 16 | M41: no comp | N41: rac_0_0_1_3 | O41: 3445 | P41: 10 | Q41: NR | R41: 25600 | T41: 0
B42: C6 | C42: llre_0_0_0_4_0_0 | D42: KHZ_15 | E42: 106 | F42: 0 | G42: 24 | H42: llre_0_0_0_4_0_0 | I42: ru-pe.0 | J42: rac_0_0_0_4 | K42: llre_0_0_0_4_0_0 | L42: 16 | M42: no comp | N42: rac_0_0_0_4 | O42: 3415 | P42: 10 | Q42: NR | R42: 25600 | T42: 0
...

Sheet CUplane-interface
A1: <rpc xmlns="urn:ietf:params:xml:ns:netconf:base:1.0" message-id="1">
A2: <edit-config>
A3: <target>
A4: <running/>
A5: </target>
A6: <default-operation>merge</default-operation>
A7: <config>
A8: <interfaces xmlns="urn:ietf:params:xml:ns:yang:ietf-interfaces">
A9: <interface>
A10: =" <name>"&'Control-Sheet'!D5&"</name>" -> <name>1000</name>
A11: <type xmlns:ianaift="urn:ietf:params:xml:ns:yang:iana-if-type">ianaift:l2vlan</type>
A12: =" <base-interface xmlns="&CHAR(34)&"urn:o-ran:interfaces:1.0"&CHAR(34)&">"&'Control-Sheet'!D6&"</base-interface>" -> <base-interface xmlns="urn:o-ran:interfaces:1.0">sys</base-interface>
A13: =" <vlan-id xmlns="&CHAR(34)&"urn:o-ran:interfaces:1.0"&CHAR(34)&">"&'Control-Sheet'!D7&"</vlan-id>" -> <vlan-id xmlns="urn:o-ran:interfaces:1.0">1000</vlan-id>
A14: =" <mac-address xmlns="&CHAR(34)&"urn:o-ran:interfaces:1.0"&CHAR(34)&">"&'Control-Sheet'!D8&"</mac-address>" -> <mac-address xmlns="urn:o-ran:interfaces:1.0">dc:c1:01:00:05:05</mac-address>
A15: <port-reference xmlns="urn:o-ran:interfaces:1.0">
A16: <port-number>0</port-number>
A17: </port-reference>
A18: </interface>
A19: </interfaces>
A20: </config>
A21: </edit-config>
A22: </rpc>

Sheet Processing-element
A1: <?xml version="1.0" encoding="UTF-8"?>
A2: <rpc xmlns="urn:ietf:params:xml:ns:netconf:base:1.0" message-id="1">
A3: <edit-config>
A4: <target>
A5: <running/>
A6: </target>
A7: <default-operation>merge</default-operation>
A8: <config>
A9: <processing-elements xmlns="urn:o-ran:processing-element:1.0">
A10: <transport-session-type>ETH-INTERFACE</transport-session-type>
A11: <ru-elements>
A12: =" <name>"&'Control-Sheet'!D13&"</name>" -> <name>ru-pe.0</name>
A13: <transport-flow>
A14: =" <interface-name>"&'Control-Sheet'!D5&"</interface-name>" -> <interface-name>1000</interface-name>
A15: <eth-flow>
A16: =" <ru-mac-address>"&'Control-Sheet'!D8&"</ru-mac-address>" -> <ru-mac-address>dc:c1:01:00:05:05</ru-mac-address>
A17: =" <vlan-id>"&'Control-Sheet'!D7&"</vlan-id>" -> <vlan-id>1000</vlan-id>
A18: =" <o-du-mac-address>"&'Control-Sheet'!D14&"</o-du-mac-address>" -> <o-du-mac-address>00:11:22:33:44:55</o-du-mac-address>
A19: </eth-flow>
A20: </transport-flow>
A21: </ru-elements>
A22: </processing-elements>
A23: </config>
A24: </edit-config>
A25: </rpc>

Sheet PDSCH
A1: <?xml version="1.0" encoding="UTF-8"?>
A2: <rpc xmlns="urn:ietf:params:xml:ns:netconf:base:1.0" message-id="1">
A3: <edit-config>
A4: <target>
A5: <running/>
A6: </target>
A7: <default-operation>merge</default-operation>
A8: <config>
A9: <user-plane-configuration xmlns="urn:o-ran:uplane-conf:1.0">
A11: =_xlfn.IFS('Control-Sheet'!$A$23="OFF", 'Control-Sheet'!$K$5, TRUE, "")
A12: <low-level-tx-endpoints>
A13: =" <name>"&'Control-Sheet'!$C23&"</name>" -> <name>llte_0_0_0_1_0_0</name>
A14: <compression>
A15: <compression-type>STATIC</compression-type>
A16: =_xlfn.IFS('Control-Sheet'!M23="exponent", 'Control-Sheet'!$G$5, 'Control-Sheet'!M23="BFP", 'Control-Sheet'!$G$6, TRUE, "")
A17: =" <iq-bitwidth>"&'Control-Sheet'!L23&"</iq-bitwidth>" -> <iq-bitwidth>16</iq-bitwidth>
A18: </compression>
A19: <frame-structure>160</frame-structure>
A20: <cp-type>NORMAL</cp-type>
A21: <cp-length>160</cp-length>
A22: <cp-length-other>144</cp-length-other>
A23: <offset-to-absolute-frequency-center>0</offset-to-absolute-frequency-center>
A24: <number-of-prb-per-scs>
A25: =" <scs>"&'Control-Sheet'!$D23&"</scs>" -> <scs>KHZ_15</scs>
A26: =" <number-of-prb>"&'Control-Sheet'!$E23&"</number-of-prb>" -> <number-of-prb>106</number-of-prb>
A27: </number-of-prb-per-scs>
A28: <e-axcid>
A29: <o-du-port-bitmask>49152</o-du-port-bitmask>
A30: <band-sector-bitmask>12288</band-sector-bitmask>
A31: <ccid-bitmask>3840</ccid-bitmask>
A32: <ru-port-bitmask>255</ru-port-bitmask>
A33: =" <eaxc-id>"&'Control-Sheet'!$F23&"</eaxc-id>" -> <eaxc-id>2</eaxc-id>
A34: </e-axcid>
A35: </low-level-tx-endpoints>
A36: <tx-array-carriers>
A37: =" <name>"&'Control-Sheet'!$K23&"</name>" -> <name>tac_0_0_0_1</name>
A38: <absolute-frequency-center>0</absolute-frequency-center>
A39: =" <center-of-channel-bandwidth>"&'Control-Sheet'!$N23*10^6&"</center-of-channel-bandwidth>" -> <center-of-channel-bandwidth>3415000000</center-of-channel-bandwidth>
A40: =" <channel-bandwidth>"&'Control-Sheet'!$O23*10^6&"</channel-bandwidth>" -> <channel-bandwidth>10000000</channel-bandwidth>
A41: <active>INACTIVE</active>
...

Sheet PUSCH
A1: <?xml version="1.0" encoding="UTF-8"?>
A2: <rpc xmlns="urn:ietf:params:xml:ns:netconf:base:1.0" message-id="2">
A3: <edit-config>
A4: <target>
A5: <running/>
A6: </target>
A7: <default-operation>merge</default-operation>
A8: <config>
A9: <user-plane-configuration xmlns="urn:o-ran:uplane-conf:1.0">
A11: =_xlfn.IFS('Control-Sheet'!$A$23="OFF", 'Control-Sheet'!$K$5, TRUE, "")
A12: <low-level-rx-endpoints>
A13: =" <name>"&'Control-Sheet'!$C36&"</name>" -> <name>llre_0_0_0_1_0_0</name>
A14: <compression>
A15: <compression-type>STATIC</compression-type>
A16: =_xlfn.IFS('Control-Sheet'!M36="exponent", 'Control-Sheet'!$G$5, 'Control-Sheet'!M36="BFP", 'Control-Sheet'!$G$6, TRUE, "")
A17: =" <iq-bitwidth>"&'Control-Sheet'!L36&"</iq-bitwidth>" -> <iq-bitwidth>16</iq-bitwidth>
A18: </compression>
A19: <frame-structure>160</frame-structure>
A20: <cp-type>NORMAL</cp-type>
A21: <cp-length>160</cp-length>
A22: <cp-length-other>144</cp-length-other>
A23: <offset-to-absolute-frequency-center>0</offset-to-absolute-frequency-center>
A24: <number-of-prb-per-scs>
A25: =" <scs>"&'Control-Sheet'!$D36&"</scs>" -> <scs>KHZ_15</scs>
A26: =" <number-of-prb>"&'Control-Sheet'!$E36&"</number-of-prb>" -> <number-of-prb>106</number-of-prb>
A27: </number-of-prb-per-scs>
A28: <ul-fft-sampling-offsets>
A29: =" <scs>"&'Control-Sheet'!$D36&"</scs>" -> <scs>KHZ_15</scs>
A30: =" <ul-fft-sampling-offset>"&'Control-Sheet'!$F36&"</ul-fft-sampling-offset>" -> <ul-fft-sampling-offset>0</ul-fft-sampling-offset>
A31: </ul-fft-sampling-offsets>
A32: <e-axcid>
A33: <o-du-port-bitmask>49152</o-du-port-bitmask>
A34: <band-sector-bitmask>12288</band-sector-bitmask>
A35: <ccid-bitmask>3840</ccid-bitmask>
A36: <ru-port-bitmask>255</ru-port-bitmask>
A37: =" <eaxc-id>"&'Control-Sheet'!$G36&"</eaxc-id>" -> <eaxc-id>18</eaxc-id>
A38: </e-axcid>
A39: </low-level-rx-endpoints>
A40: <rx-array-carriers>
A41: =" <name>"&'Control-Sheet'!$N36&"</name>" -> <name>rac_0_0_0_1</name>
...

Sheet PRACH
A1: <?xml version="1.0" encoding="UTF-8"?>
A2: <rpc xmlns="urn:ietf:params:xml:ns:netconf:base:1.0" message-id="1">
A3: <edit-config>
A4: <target>
A5: <running/>
A6: </target>
A7: <default-operation>merge</default-operation>
A8: <config>
A9: <user-plane-configuration xmlns="urn:o-ran:uplane-conf:1.0">
A11: =_xlfn.IFS('Control-Sheet'!$A$23="OFF", 'Control-Sheet'!$K$5, TRUE, "")
A12: <low-level-rx-endpoints>
A13: =" <name>"&'Control-Sheet'!$C49&"</name>" -> <name>llre_0_0_0_1_1_0</name>
A14: <compression>
A15: <compression-type>STATIC</compression-type>
A16: =_xlfn.IFS('Control-Sheet'!M49="exponent", 'Control-Sheet'!$G$5, 'Control-Sheet'!M49="BFP", 'Control-Sheet'!$G$6, TRUE, "")
A17: =" <iq-bitwidth>"&'Control-Sheet'!L49&"</iq-bitwidth>" -> <iq-bitwidth>16</iq-bitwidth>
A18: </compression>
A19: <frame-structure>160</frame-structure>
A20: <cp-type>NORMAL</cp-type>
A21: <cp-length>160</cp-length>
A22: <cp-length-other>144</cp-length-other>
A23: <offset-to-absolute-frequency-center>0</offset-to-absolute-frequency-center>
A24: <number-of-prb-per-scs>
A25: =" <scs>"&'Control-Sheet'!$D49&"</scs>" -> <scs>KHZ_15</scs>
A26: =" <number-of-prb>"&'Control-Sheet'!$E49&"</number-of-prb>" -> <number-of-prb></number-of-prb>
A27: </number-of-prb-per-scs>
A28: <ul-fft-sampling-offsets>
A29: =" <scs>"&'Control-Sheet'!$D49&"</scs>" -> <scs>KHZ_15</scs>
A30: =" <ul-fft-sampling-offset>"&'Control-Sheet'!$F49&"</ul-fft-sampling-offset>" -> <ul-fft-sampling-offset>0</ul-fft-sampling-offset>
A31: </ul-fft-sampling-offsets>
A32: <e-axcid>
A33: <o-du-port-bitmask>49152</o-du-port-bitmask>
A34: <band-sector-bitmask>12288</band-sector-bitmask>
A35: <ccid-bitmask>3840</ccid-bitmask>
A36: <ru-port-bitmask>255</ru-port-bitmask>
A37: =" <eaxc-id>"&'Control-Sheet'!$G49&"</eaxc-id>" -> <eaxc-id>34</eaxc-id>
A38: </e-axcid>
A39: </low-level-rx-endpoints>
A40: <low-level-rx-links>
A41: =" <name>"&'Control-Sheet'!$H49&"</name>" -> <name>llre_0_0_0_1_1_0</name>
...

Sheet ACTIVE
A1: <rpc message-id="30" xmlns="urn:ietf:params:xml:ns:netconf:base:1.0">
A2: <edit-config>
A3: <target>
A4: <running/>
A5: </target>
A6: <config>
A7: <user-plane-configuration xmlns="urn:o-ran:uplane-conf:1.0">
A9: =_xlfn.IFS('Control-Sheet'!$A$23="OFF", 'Control-Sheet'!$K$5, TRUE, "")
A10: <tx-array-carriers>
A11: =" <name>"&'Control-Sheet'!$K25&"</name>" -> <name>tac_0_0_0_2</name>
A12: <active>ACTIVE</active>
A13: </tx-array-carriers>
A14: =_xlfn.IFS('Control-Sheet'!$A$23="OFF", 'Control-Sheet'!$K$6, TRUE, "")
A15: =_xlfn.IFS('Control-Sheet'!$A$24="OFF", 'Control-Sheet'!$K$5, TRUE, "")
A16: <tx-array-carriers>
A17: =" <name>"&'Control-Sheet'!$K25&"</name>" -> <name>tac_0_0_0_2</name>
A18: <active>ACTIVE</active>
A19: </tx-array-carriers>
A20: =_xlfn.IFS('Control-Sheet'!$A$24="OFF", 'Control-Sheet'!$K$6, TRUE, "")
A21: =_xlfn.IFS('Control-Sheet'!$A$25="OFF", 'Control-Sheet'!$K$5, TRUE, "")
A22: <tx-array-carriers>
A23: =" <name>"&'Control-Sheet'!$K25&"</name>" -> <name>tac_0_0_0_2</name>
A24: <active>ACTIVE</active>
A25: </tx-array-carriers>
A26: =_xlfn.IFS('Control-Sheet'!$A$25="OFF", 'Control-Sheet'!$K$6, TRUE, "")
A27: =_xlfn.IFS('Control-Sheet'!$A$26="OFF", 'Control-Sheet'!$K$5, TRUE, "")
A28: <tx-array-carriers>
A29: =" <name>"&'Control-Sheet'!$K26&"</name>" -> <name>tac_0_0_1_2</name>
A30: <active>ACTIVE</active>
A31: </tx-array-carriers>
A32: =_xlfn.IFS('Control-Sheet'!$A$26="OFF", 'Control-Sheet'!$K$6, TRUE, "")
A33: =_xlfn.IFS('Control-Sheet'!$A$27="OFF", 'Control-Sheet'!$K$5, TRUE, "")
A34: <tx-array-carriers>
A35: =" <name>"&'Control-Sheet'!$K27&"</name>" -> <name>tac_0_0_0_3</name>
A36: <active>ACTIVE</active>
A37: </tx-array-carriers>
A38: =_xlfn.IFS('Control-Sheet'!$A$27="OFF", 'Control-Sheet'!$K$6, TRUE, "")
A39: =_xlfn.IFS('Control-Sheet'!$A$28="OFF", 'Control-Sheet'!$K$5, TRUE, "")
A40: <tx-array-carriers>
A41: =" <name>"&'Control-Sheet'!$K28&"</name>" -> <name>tac_0_0_1_3</name>
...
