Workbook

Sheet Control-Sheet
B3: 1. Cuplane-interface | O3: NR | Q3: LTE
G4: 삭제 금지 | N4: BW | O4: KHZ_15 | P4: KHZ_30 | Q4: KHZ_15
C5: name | D5: DLPU_DSD1 | E5: VLAN NAME | G5: <exponent>4</exponent> | K5: <!-- | N5: 5 | O5: 25 | P5: 11 | Q5: 25
C6: Base-interface | D6: sys | E6: 고정 | G6: <compression-method>BLOCK_FLOATING_POINT</compression-method> | K6: --> | N6: 10 | O6: 52 | P6: 24 | Q6: 50
C7: vlan id | D7: 1000 | N7: 15 | O7: 79 | P7: 38 | Q7: 75
C8: ORU mac-address | D8: 00:0a:35:00:00:02 | E8: nDLPU MAC | N8: 20 | O8: 106 | P8: 51 | Q8: 100
N9: 25 | O9: 216 | P9: 65
N10: 30 | O10: 270 | P10: 78
B11: 2. Processing element | N11: 40 | P11: 106
N12: 50 | P12: 133
C13: name | D13: ru-pe.0 | E13: oran player | N13: 60 | P13: 162
C14: ODU mac-address | D14: 80:09:02:03:04:05 | E14: 변경 가능 고정 사용 | N14: 80 | P14: 217
N15: 90 | P15: 245
N16: 100 | P16: 273
R17: 0.509
R18: Tc = 1 / (480kHz · 4096) = 0.509 ns
B19: 3. PDSCH | R19: TC =~ 0.5 ns = 1/1.96608GHz | W19: <exponent>4<exponent>
R20: 10000
C21: end-point | G21: link | K21: array-carrier | R21: 100 | S21: 6.81
C22: name | D22: scs | E22: number-of-prb | F22: eaxc-id | G22: name | H22: processing-element | I22: rx-array-carrier | J22: low-level-rx-endpoint | K22: name | L22: iq-bitwidth | M22: compression | N22: Center-FREQ | O22: Channel-BW | P22: type | Q22: gain | R22: T-da-offset
B23: C0 | C23: llte_0_0_0_1_0_0 | D23: KHZ_30 | E23: 133 | F23: 2 | G23: llte_0_0_0_1_0_0 | H23: ru-pe.0 | I23: tac_0_0_0_1 | J23: llte_0_0_0_1_0_0 | K23: tac_0_0_0_1 | L23: 9 | M23: BFP | N23: 3900 | O23: 50000000 | P23: NR | Q23: 0 | R23: 19646 | T23: 6.8 | V23: =DEC2HEX(F23) | W23: 7
B24: C1 | C24: llte_0_0_1_1_0_0 | D24: KHZ_30 | E24: 133 | F24: 3 | G24: llte_0_0_1_1_0_0 | H24: ru-pe.0 | I24: tac_0_0_1_1 | J24: llte_0_0_1_1_0_0 | K24: tac_0_0_1_1 | L24: 9 | M24: BFP | N24: 3950 | O24: 50000000 | P24: NR | Q24: 0 | R24: 19646 | T24: 4.2 | V24: =DEC2HEX(F24) | W24: =W23
B25: C2 | C25: llte_0_1_0_2_0_0 | D25: KHZ_15 | E25: 106 | F25: 4 | G25: llte_0_1_0_2_0_0 | H25: ru-pe.0 | I25: tac_0_1_0_2 | J25: llte_0_1_0_2_0_0 | K25: tac_0_1_0_2 | L25: 9 | M25: BFP | N25: 1940 | O25: 20000000 | P25: NR | Q25: 0 | R25: 19646 | V25: =DEC2HEX(F25) | W25: =W24
B26: C3 | C26: llte_0_1_1_2_0_0 | D26: KHZ_15 | E26: 106 | F26: 5 | G26: llte_0_1_1_2_0_0 | H26: ru-pe.0 | I26: tac_0_1_1_2 | J26: llte_0_1_1_2_0_0 | K26: tac_0_1_1_2 | L26: 9 | M26: BFP | N26: 1960 | O26: 20000000 | P26: NR | Q26: 0 | R26: 19646 | V26: =DEC2HEX(F26) | W26: =W25
B27: C4 | C27: llte_0_2_0_3_0_0 | D27: KHZ_15 | E27: 25 | F27: 6 | G27: llte_0_2_0_3_0_0 | H27: ru-pe.0 | I27: tac_0_2_0_3 | J27: llte_0_2_0_3_0_0 | K27: tac_0_2_0_3 | L27: 9 | M27: BFP | N27: 864.5 | O27: 5000000 | P27: NR | Q27: 0 | R27: 19646 | V27: =DEC2HEX(F27) | W27: =W26 | AH27: UL Center
B28: C5 | C28: llte_0_2_1_3_0_0 | D28: KHZ_15 | E28: 25 | F28: 7 | G28: llte_0_2_1_3_0_0 | H28: ru-pe.0 | I28: tac_0_2_1_3 | J28: llte_0_2_1_3_0_0 | K28: tac_0_2_1_3 | L28: 9 | M28: BFP | N28: 869.5 | O28: 5000000 | P28: NR | Q28: 0 | R28: 19646 | V28: =DEC2HEX(F28) | W28: =W27 | AH28: 3900
B29: C6 | C29: llte_0_3_0_4_0_0 | D29: KHZ_15 | E29: 25 | F29: 8 | G29: llte_0_3_0_4_0_0 | H29: ru-pe.0 | I29: tac_0_3_0_4 | J29: llte_0_3_0_4_0_0 | K29: tac_0_3_0_4 | L29: 9 | M29: BFP | N29: 2352.5 | O29: 5000000 | P29: NR | Q29: 0 | R29: 19646 | V29: =DEC2HEX(F29) | W29: =W28
B30: C7 | C30: llte_0_3_1_4_0_0 | D30: KHZ_15 | E30: 25 | F30: 9 | G30: llte_0_3_1_4_0_0 | H30: ru-pe.0 | I30: tac_0_3_1_4 | J30: llte_0_3_1_4_0_0 | K30: tac_0_3_1_4 | L30: 9 | M30: BFP | N30: 2357.5 | O30: 5000000 | P30: NR | Q30: 0 | R30: 19646 | V30: =DEC2HEX(F30) | W30: =W29
C31: 고정 | F31: dec (oran은 hex로) | G31: 가능하나 고정 | H31: 가능하나 고정 | I31: 가능하나 고정 | J31: =C31 | K31: 가능하나 고정
B32: 4. PUSCH | S32: TC =~ 0.5 ns = 1/1.96608GHz
R33: =R36*R17 | S33: =S34*1000 | V33: =R34 | W33: =V33/1000 | X33: 10 | Y33: =X33-W33
C34: end-point | H34: link | N34: array-carrier | R34: =R33/1000 | S34: 100 | T34: 1.89 | U34: 4.09 | V34: =S34+R34 | W34: =V34/1000 | X34: 10 | Y34: =X34-W34
C35: name | D35: scs | E35: number-of-prb | F35: ul-fft-sampling-offset | G35: eaxc-id | H35: name | I35: processing-element | J35: rx-array-carrier | K35: low-level-rx-endpoint | L35: iq-bitwidth | M35: compression | N35: name | O35: Center-FREQ | P35: Channel-BW | Q35: type | R35: n-ta-offset | S35: T-au-offset | T35: Gain-Correction
B36: C0 | C36: llre_0_0_0_1_0_0 | D36: KHZ_15 | E36: 133 | F36: 0 | G36: 18 | H36: llre_0_0_0_1_0_0 | I36: ru-pe.0 | J36: rac_0_0_0_1 | K36: llre_0_0_0_1_0_0 | L36: 9 | M36: BFP | N36: rac_0_0_0_1 | O36: 3900 | P36: 50000000 | Q36: NR | R36: 25600 | S36: 19646 | T36: 0
B37: C1 | C37: llre_0_0_1_1_0_0 | D37: KHZ_15 | E37: 133 | F37: 0 | G37: 19 | H37: llre_0_0_1_1_0_0 | I37: ru-pe.0 | J37: rac_0_0_1_1 | K37: llre_0_0_1_1_0_0 | L37: 9 | M37: BFP | N37: rac_0_0_1_1 | O37: 3950 | P37: 50000000 | Q37: NR | R37: 25600 | S37: 19646 | T37: 0
B38: C2 | C38: llre_0_1_0_2_0_0 | D38: KHZ_15 | E38: 106 | F38: 0 | G38: 20 | H38: llre_0_1_0_2_0_0 | I38: ru-pe.0 | J38: rac_0_1_0_2 | K38: llre_0_1_0_2_0_0 | L38: 9 | M38: BFP | N38: rac_0_1_0_2 | O38: 1860 | P38: 20000000 | Q38: NR | R38: 25600 | S38: 19646 | T38: 0
B39: C3 | C39: llre_0_1_1_2_0_0 | D39: KHZ_15 | E39: 106 | F39: 0 | G39: 21 | H39: llre_0_1_1_2_0_0 | I39: ru-pe.0 | J39: rac_0_1_1_2 | K39: llre_0_1_1_2_0_0 | L39: 9 | M39: BFP | N39: rac_0_1_1_2 | O39: 1880 | P39: 20000000 | Q39: NR | R39: 25600 | S39: 19646 | T39: 0
B40: C4 | C40: llre_0_2_0_3_0_0 | D40: KHZ_15 | E40: 25 | F40: 0 | G40: 22 | H40: llre_0_2_0_3_0_0 | I40: ru-pe.0 | J40: rac_0_2_0_3 | K40: llre_0_2_0_3_0_0 | L40: 9 | M40: BFP | N40: rac_0_2_0_3 | O40: 832 | P40: 5000000 | Q40: NR | R40: 25600 | S40: 19646 | T40: 0
B41: C5 | C41: llre_0_2_1_3_0_0 | D41: KHZ_15 | E41: 25 | F41: 0 | G41: 23 | H41: llre_0_2_1_3_0_0 | I41: ru-pe.0 | J41: rac_0_2_1_3 | K41: llre_0_2_1_3_0_0 | L41: 9 | M41: BFP | N41: rac_0_2_1_3 | O41: 837 | P41: 5000000 | Q41: NR | R41: 25600 | S41: 19646 | T41: 0
B42: C6 | C42: llre_0_3_0_4_0_0 | D42: KHZ_15 | E42: 25 | F42: 0 | G42: 24 | H42: llre_0_3_0_4_0_0 | I42: ru-pe.0 | J42: rac_0_3_0_4 | K42: llre_0_3_0_4_0_0 | L42: 9 | M42: BFP | N42: rac_0_3_0_4 | O42: 2307.5 | P42: 5000000 | Q42: NR | R42: 25600 | S42: 19646 | T42: 0
...

Sheet CUplane-interface
A2: <rpc xmlns="urn:ietf:params:xml:ns:netconf:base:1.0" message-id="1">
A3: <edit-config>
A4: <target>
A5: <running/>
A6: </target>
A7: <default-operation>merge</default-operation>
A8: <config>
A9: <interfaces xmlns="urn:ietf:params:xml:ns:yang:ietf-interfaces">
A10: <interface>
A11: =" <name>"&'Control-Sheet'!D5&"</name>"
A12: <type xmlns:ianaift="urn:ietf:params:xml:ns:yang:iana-if-type">ianaift:l2vlan</type>
A13: =" <base-interface xmlns="&CHAR(34)&"urn:o-ran:interfaces:1.0"&CHAR(34)&">"&'Control-Sheet'!D6&"</base-interface>"
A14: =" <vlan-id xmlns="&CHAR(34)&"urn:o-ran:interfaces:1.0"&CHAR(34)&">"&'Control-Sheet'!D7&"</vlan-id>"
A15: =" <mac-address xmlns="&CHAR(34)&"urn:o-ran:interfaces:1.0"&CHAR(34)&">"&'Control-Sheet'!D8&"</mac-address>"
A16: <port-reference xmlns="urn:o-ran:interfaces:1.0">
A17: <port-number>0</port-number>
A18: </port-reference>
A19: </interface>
A20: </interfaces>
A21: </config>
A22: </edit-config>
A23: </rpc>

Sheet Processing-element
A1: <?xml version="1.0" encoding="UTF-8"?>
A2: <rpc xmlns="urn:ietf:params:xml:ns:netconf:base:1.0" message-id="1">
A3: <edit-config>
A4: <target>
A5: <running/>
A6: </target>
A7: <default-operation>merge</default-operation>
A8: <config>
A9: <processing-elements xmlns="urn:o-ran:processing-element:1.0">
A10: <transport-session-type>ETH-INTERFACE</transport-session-type>
A11: <ru-elements>
A12: =" <name>"&'Control-Sheet'!D13&"</name>"
A13: <transport-flow>
A14: =" <interface-name>"&'Control-Sheet'!D5&"</interface-name>"
A15: <eth-flow>
A16: =" <ru-mac-address>"&'Control-Sheet'!D8&"</ru-mac-address>"
A17: =" <vlan-id>"&'Control-Sheet'!D7&"</vlan-id>"
A18: =" <o-du-mac-address>"&'Control-Sheet'!D14&"</o-du-mac-address>"
A19: </eth-flow>
A20: </transport-flow>
A21: </ru-elements>
A22: </processing-elements>
A23: </config>
A24: </edit-config>
A25: </rpc>

Sheet PDSCH
A1: <?xml version="1.0" encoding="UTF-8"?>
A2: <rpc xmlns="urn:ietf:params:xml:ns:netconf:base:1.0" message-id="1">
A3: <edit-config>
A4: <target>
A5: <running/>
A6: </target>
A7: <default-operation>merge</default-operation>
A8: <config>
A9: <user-plane-configuration xmlns="urn:o-ran:uplane-conf:1.0">
A11: =_xlfn.IFS('Control-Sheet'!#REF!="OFF", 'Control-Sheet'!$K$5, TRUE, "")
A12: <low-level-tx-endpoints>
A13: =" <name>"&'Control-Sheet'!$C23&"</name>"
A14: <compression>
A15: <compression-type>STATIC</compression-type>
A16: =_xlfn.IFS('Control-Sheet'!M23="exponent", 'Control-Sheet'!$G$5, 'Control-Sheet'!M23="BFP", 'Control-Sheet'!$G$6, TRUE, "")
A17: =" <iq-bitwidth>"&'Control-Sheet'!L23&"</iq-bitwidth>"
A18: </compression>
A19: <frame-structure>160</frame-structure>
A20: <cp-type>NORMAL</cp-type>
A21: <cp-length>160</cp-length>
A22: <cp-length-other>144</cp-length-other>
A23: <offset-to-absolute-frequency-center>0</offset-to-absolute-frequency-center>
A24: <number-of-prb-per-scs>
A25: =" <scs>"&'Control-Sheet'!$D23&"</scs>"
A26: =" <number-of-prb>"&'Control-Sheet'!$E23&"</number-of-prb>"
A27: </number-of-prb-per-scs>
A28: <e-axcid>
A29: <o-du-port-bitmask>49152</o-du-port-bitmask>
A30: <band-sector-bitmask>12288</band-sector-bitmask>
A31: <ccid-bitmask>3840</ccid-bitmask>
A32: <ru-port-bitmask>255</ru-port-bitmask>
A33: =" <eaxc-id>"&'Control-Sheet'!$F23&"</eaxc-id>"
A34: </e-axcid>
A35: </low-level-tx-endpoints>
A36: <tx-array-carriers>
A37: =" <name>"&'Control-Sheet'!$K23&"</name>"
A38: <absolute-frequency-center>0</absolute-frequency-center>
A39: =" <center-of-channel-bandwidth>"&'Control-Sheet'!$N23*10^6&"</center-of-channel-bandwidth>"
A40: =" <channel-bandwidth>"&'Control-Sheet'!$O23*10^6&"</channel-bandwidth>"
A41: <active>INACTIVE</active>
...

Sheet PUSCH
A1: <?xml version="1.0" encoding="UTF-8"?>
A2: <rpc xmlns="urn:ietf:params:xml:ns:netconf:base:1.0" message-id="2">
A3: <edit-config>
A4: <target>
A5: <running/>
A6: </target>
A7: <default-operation>merge</default-operation>
A8: <config>
A9: <user-plane-configuration xmlns="urn:o-ran:uplane-conf:1.0">
A11: =_xlfn.IFS('Control-Sheet'!#REF!="OFF", 'Control-Sheet'!$K$5, TRUE, "")
A12: <low-level-rx-endpoints>
A13: =" <name>"&'Control-Sheet'!$C36&"</name>"
A14: <compression>
A15: <compression-type>STATIC</compression-type>
A16: =_xlfn.IFS('Control-Sheet'!M36="exponent", 'Control-Sheet'!$G$5, 'Control-Sheet'!M36="BFP", 'Control-Sheet'!$G$6, TRUE, "")
A17: =" <iq-bitwidth>"&'Control-Sheet'!L36&"</iq-bitwidth>"
A18: </compression>
A19: <frame-structure>160</frame-structure>
A20: <cp-type>NORMAL</cp-type>
A21: <cp-length>160</cp-length>
A22: <cp-length-other>144</cp-length-other>
A23: <offset-to-absolute-frequency-center>0</offset-to-absolute-frequency-center>
A24: <number-of-prb-per-scs>
A25: =" <scs>"&'Control-Sheet'!$D36&"</scs>"
A26: =" <number-of-prb>"&'Control-Sheet'!$E36&"</number-of-prb>"
A27: </number-of-prb-per-scs>
A28: <ul-fft-sampling-offsets>
A29: =" <scs>"&'Control-Sheet'!$D36&"</scs>"
A30: =" <ul-fft-sampling-offset>"&'Control-Sheet'!$F36&"</ul-fft-sampling-offset>"
A31: </ul-fft-sampling-offsets>
A32: <e-axcid>
A33: <o-du-port-bitmask>49152</o-du-port-bitmask>
A34: <band-sector-bitmask>12288</band-sector-bitmask>
A35: <ccid-bitmask>3840</ccid-bitmask>
A36: <ru-port-bitmask>255</ru-port-bitmask>
A37: =" <eaxc-id>"&'Control-Sheet'!$G36&"</eaxc-id>"
A38: </e-axcid>
A39: </low-level-rx-endpoints>
A40: <rx-array-carriers>
A41: =" <name>"&'Control-Sheet'!$N36&"</name>"
...

Sheet PRACH
A1: <?xml version="1.0" encoding="UTF-8"?>
A2: <rpc xmlns="urn:ietf:params:xml:ns:netconf:base:1.0" message-id="1">
A3: <edit-config>
A4: <target>
A5: <running/>
A6: </target>
A7: <default-operation>merge</default-operation>
A8: <config>
A9: <user-plane-configuration xmlns="urn:o-ran:uplane-conf:1.0">
A11: =_xlfn.IFS('Control-Sheet'!#REF!="OFF", 'Control-Sheet'!$K$5, TRUE, "")
A12: <low-level-rx-endpoints>
A13: =" <name>"&'Control-Sheet'!$C49&"</name>"
A14: <compression>
A15: <compression-type>STATIC</compression-type>
A16: =_xlfn.IFS('Control-Sheet'!M49="exponent", 'Control-Sheet'!$G$5, 'Control-Sheet'!M49="BFP", 'Control-Sheet'!$G$6, TRUE, "")
A17: =" <iq-bitwidth>"&'Control-Sheet'!L49&"</iq-bitwidth>"
A18: </compression>
A19: <frame-structure>160</frame-structure>
A20: <cp-type>NORMAL</cp-type>
A21: <cp-length>160</cp-length>
A22: <cp-length-other>144</cp-length-other>
A23: <offset-to-absolute-frequency-center>0</offset-to-absolute-frequency-center>
A24: <number-of-prb-per-scs>
A25: =" <scs>"&'Control-Sheet'!$D49&"</scs>"
A26: =" <number-of-prb>"&'Control-Sheet'!$E49&"</number-of-prb>"
A27: </number-of-prb-per-scs>
A28: <ul-fft-sampling-offsets>
A29: =" <scs>"&'Control-Sheet'!$D49&"</scs>"
A30: =" <ul-fft-sampling-offset>"&'Control-Sheet'!$F49&"</ul-fft-sampling-offset>"
A31: </ul-fft-sampling-offsets>
A32: <e-axcid>
A33: <o-du-port-bitmask>49152</o-du-port-bitmask>
A34: <band-sector-bitmask>12288</band-sector-bitmask>
A35: <ccid-bitmask>3840</ccid-bitmask>
A36: <ru-port-bitmask>255</ru-port-bitmask>
A37: =" <eaxc-id>"&'Control-Sheet'!$G49&"</eaxc-id>"
A38: </e-axcid>
A39: </low-level-rx-endpoints>
A40: <low-level-rx-links>
A41: =" <name>"&'Control-Sheet'!$H49&"</name>"
...

Sheet ACTIVE
A1: <rpc message-id="30" xmlns="urn:ietf:params:xml:ns:netconf:base:1.0">
A2: <edit-config>
A3: <target>
A4: <running/>
A5: </target>
A6: <config>
A7: <user-plane-configuration xmlns="urn:o-ran:uplane-conf:1.0">
A9: =_xlfn.IFS('Control-Sheet'!#REF!="OFF", 'Control-Sheet'!$K$5, TRUE, "")
A10: <tx-array-carriers>
A11: =" <name>"&'Control-Sheet'!$K23&"</name>"
A12: <active>ACTIVE</active>
A13: </tx-array-carriers>
A14: <tx-array-carriers>
A15: =" <name>"&'Control-Sheet'!$K24&"</name>"
A16: <active>ACTIVE</active>
A17: </tx-array-carriers>
A18: =_xlfn.IFS('Control-Sheet'!#REF!="OFF", 'Control-Sheet'!$K$6, TRUE, "")
A19: =_xlfn.IFS('Control-Sheet'!#REF!="OFF", 'Control-Sheet'!$K$5, TRUE, "")
A20: <tx-array-carriers>
A21: =" <name>"&'Control-Sheet'!$K25&"</name>"
A22: <active>ACTIVE</active>
A23: </tx-array-carriers>
A24: <tx-array-carriers>
A25: =" <name>"&'Control-Sheet'!$K26&"</name>"
A26: <active>ACTIVE</active>
A27: </tx-array-carriers>
A28: =_xlfn.IFS('Control-Sheet'!#REF!="OFF", 'Control-Sheet'!$K$6, TRUE, "")
A29: =_xlfn.IFS('Control-Sheet'!#REF!="OFF", 'Control-Sheet'!$K$5, TRUE, "")
A30: <tx-array-carriers>
A31: =" <name>"&'Control-Sheet'!$K27&"</name>"
A32: <active>ACTIVE</active>
A33: </tx-array-carriers>
A34: <tx-array-carriers>
A35: =" <name>"&'Control-Sheet'!$K28&"</name>"
A36: <active>ACTIVE</active>
A37: </tx-array-carriers>
A38: =_xlfn.IFS('Control-Sheet'!#REF!="OFF", 'Control-Sheet'!$K$6, TRUE, "")
A39: =_xlfn.IFS('Control-Sheet'!#REF!="OFF", 'Control-Sheet'!$K$5, TRUE, "")
A40: <tx-array-carriers>
A41: =" <name>"&'Control-Sheet'!$K29&"</name>"
...

Sheet LLTE,LLRE
F6: Interface | G6: Band/Sector | H6: CC | I6: Spatial stream | J6: PUxCH&PRACH
E7: low-level-tx-endpoint | F7: 0 | G7: 0 | H7: 0 | I7: 1 | J7: 0 | K7: 0
F8: 0 | G8: 0 | H8: 1 | I8: 1 | J8: 0 | K8: 0
E9: low-level-rx-endpoint

Sheet RSRP_EffBW
E38: RSRP offset | F38: measured RSRP | H38: RSRQ | M38: BW(kHz) | N38: symbols | O38: SCS | P38: No of RB | Q38: Effective BW | R38: % | S38: Guardband | T38: Eg to Eg | V38: D filter
B39: BW | C39: SCS | D39: RB | E39: Referance power offset | F39: measured reference power | G39: RSSI | L39: NR | M39: 5000 | N39: 12 | O39: 15 | P39: 25 | Q39: =P39*O39*N39 | R39: =Q39/M39 | S39: =(M39-P39*O39*N39)/2-O39/2 | T39: =S39*2 | U39: -> | V39: 450 | W39: ?
B40: 20 | C40: 30 | D40: 51 | E40: =10*LOG(12*D40) | F40: -15 | G40: =F40-(-E40) | H40: =10*LOG(D40)+F40-G40 | M40: =M39 | N40: 12 | O40: 30 | P40: 11 | Q40: =P40*O40*N40 | R40: =Q40/M40 | S40: =(M40-P40*O40*N40)/2-O40/2 | T40: =S40*2 | U40: -> | V40: 1000 | W40: ?
B41: 20 | C41: 15 | D41: 106 | E41: =10*LOG(12*D41) | F41: -15 | G41: =F41-(-E41) | H41: =10*LOG(D41)+F41-G41 | L41: LTE | M41: =M39 | N41: 12 | O41: 15 | P41: 25 | Q41: =P41*O41*N41 | R41: =Q41/M41 | S41: =(M41-P41*O41*N41)/2-O41/2 | T41: =S41*2 | U41: -> | V41: 450 | W41: ?
C43: 84 | D43: 14 | E43: =C43/D43 | L43: NR | M43: 20000 | N43: 12 | O43: 15 | P43: 106 | Q43: =P43*O43*N43 | R43: =Q43/M43 | S43: =(M43-P43*O43*N43)/2-O43/2 | T43: =S43*2 | U43: -> | V43: 900 | W43: ?
M44: =M43 | N44: 12 | O44: 30 | P44: 51 | Q44: =P44*O44*N44 | R44: =Q44/M44 | S44: =(M44-P44*O44*N44)/2-O44/2 | T44: =S44*2
B45: 100 | C45: 30 | D45: 273 | E45: =10*LOG(12*D45) | F45: -22.8 | G45: =F45-(-E45) | H45: =10*LOG(D45)+F45-G45 | L45: LTE | M45: =M43 | N45: 12 | O45: 15 | P45: 100 | Q45: =P45*O45*N45 | R45: =Q45/M45 | S45: =(M45-P45*O45*N45)/2-O45/2 | T45: =S45*2
D46: =10^(E46/10)/12 | E46: =G46-F46 | F46: -22.8 | G46: 0.31
D47: 17 | E47: =10*LOG(12*D47) | F47: -22.87 | G47: =E47+F47-H47 | H47: -10.167 | I47: =G47-F47-H47 | L47: NR | M47: 40000 | N47: 12 | O47: 15 | P47: 216 | Q47: =P47*O47*N47 | R47: =Q47/M47 | S47: =(M47-P47*O47*N47)/2-O47/2 | T47: =S47*2 | U47: -> | V47: =ROUND(T47,0.001) | W47: ?
M48: =M47 | N48: 12 | O48: 30 | P48: 106 | Q48: =P48*O48*N48 | R48: =Q48/M48 | S48: =(M48-P48*O48*N48)/2-O48/2 | T48: =S48*2
D49: S-SS RB수
B50: 100 | C50: 30 | D50: 20 | E50: =10*LOG(12*D50) | F50: -22.87 | G50: =F50-(-E50) | H50: =10*LOG(D50)+F50-G50 | L50: NR | M50: 100000 | N50: 12 | O50: 30 | P50: 273 | Q50: =P50*O50*N50 | R50: =Q50/M50 | S50: =(M50-P50*O50*N50)/2-O50/2 | T50: =S50*2 | U50: -> | V50: 1400 | W50: 60
V51: 900 | W51: 17
V52: 400 | W52: 3
M55: BW(kHz) | N55: symbols | O55: SCS | P55: No of RB | Q55: Effective BW | R55: % | S55: Guardband | T55: Eg to Eg
L56: NR | M56: 5000 | N56: 12 | O56: 15 | P56: 25 | Q56: =P56*O56*N56 | R56: =Q56/M56 | S56: =(M56-P56*O56*N56)/2-O56/2 | T56: =S56*2
M57: =M56 | N57: 12 | O57: 30 | P57: 11 | Q57: =P57*O57*N57 | R57: =Q57/M57 | S57: =(M57-P57*O57*N57)/2-O57/2 | T57: =S57*2
L58: LTE | M58: =M56 | N58: 12 | O58: 15 | P58: 25 | Q58: =P58*O58*N58 | R58: =Q58/M58 | S58: =(M58-P58*O58*N58)/2-O58/2 | T58: =S58*2
L60: NR | M60: 10000 | N60: 12 | O60: 15 | P60: 52 | Q60: =P60*O60*N60 | R60: =Q60/M60 | S60: =(M60-P60*O60*N60)/2-O60/2 | T60: =S60*2
M61: =M60 | N61: 12 | O61: 30 | P61: 24 | Q61: =P61*O61*N61 | R61: =Q61/M61 | S61: =(M61-P61*O61*N61)/2-O61/2 | T61: =S61*2
L62: LTE | M62: =M60 | N62: 12 | O62: 15 | P62: 50 | Q62: =P62*O62*N62 | R62: =Q62/M62 | S62: =(M62-P62*O62*N62)/2-O62/2 | T62: =S62*2
L64: NR | M64: 20000 | N64: 12 | O64: 15 | P64: 106 | Q64: =P64*O64*N64 | R64: =Q64/M64 | S64: =(M64-P64*O64*N64)/2-O64/2 | T64: =S64*2 | W64: @ | X64: ATTEN
M65: =M64 | N65: 12 | O65: 30 | P65: 51 | Q65: =P65*O65*N65 | R65: =Q65/M65 | S65: =(M65-P65*O65*N65)/2-O65/2 | T65: =S65*2 | V65: windowing filter | W65: 400 | X65: 3
L66: LTE | M66: =M64 | N66: 12 | O66: 15 | P66: 100 | Q66: =P66*O66*N66 | R66: =Q66/M66 | S66: =(M66-P66*O66*N66)/2-O66/2 | T66: =S66*2 | W66: 900 | X66: 17
W67: 1400 | X67: 60
L68: NR | M68: 40000 | N68: 12 | O68: 15 | P68: 216 | Q68: =P68*O68*N68 | R68: =Q68/M68 | S68: =(M68-P68*O68*N68)/2-O68/2 | T68: =S68*2
M69: =M68 | N69: 12 | O69: 30 | P69: 106 | Q69: =P69*O69*N69 | R69: =Q69/M69 | S69: =(M69-P69*O69*N69)/2-O69/2 | T69: =S69*2
L71: NR | M71: 100000 | N71: 12 | O71: 30 | P71: 273 | Q71: =P71*O71*N71 | R71: =Q71/M71 | S71: =(M71-P71*O71*N71)/2-O71/2 | T71: =S71*2
