Workbook

Sheet Control-Sheet
B3: 1. Cuplane-interface | O3: NR | Q3: LTE
N4: BW | O4: KHZ_15 | P4: KHZ_30 | Q4: KHZ_15
C5: name | D5: DLPU_DSD1 | E5: VLAN NAME | G5: <exponent>4</exponent> | N5: 5 | O5: 25 | P5: 11 | Q5: 25
C6: Base-interface | D6: sys | E6: 고정 | G6: <compression-method>BLOCK_FLOATING_POINT</compression-method> | N6: 10 | O6: 52 | P6: 24 | Q6: 50
C7: vlan id | D7: 1000 | N7: 15 | O7: 79 | P7: 38 | Q7: 75
C8: ORU mac-address | D8: 00:0a:35:00:00:02 | E8: nDLPU MAC | N8: 20 | O8: 106 | P8: 51 | Q8: 100
N9: 25 | O9: 216 | P9: 65
N10: 30 | O10: 270 | P10: 78
B11: 2. Processing element | N11: 40 | P11: 106
N12: 50 | P12: 133
C13: name | D13: ru-pe.0 | E13: oran player | N13: 60 | P13: 162
C14: ODU mac-address | D14: 80:09:02:03:04:05 | E14: 변경 가능 고정 사용 | N14: 80 | P14: 217
N15: 90 | P15: 245
N16: 100 | P16: 273
B19: 3. PDSCH
C21: end-point | G21: link | K21: array-carrier | R21: 100 | S21: 6.81
C22: name | D22: scs | E22: number-of-prb | F22: eaxc-id | G22: name | H22: processing-element | I22: rx-array-carrier | J22: low-level-rx-endpoint | K22: name | L22: iq-bitwidth | M22: compression | N22: Center-FREQ | O22: Channel-BW | P22: type | Q22: gain | R22: T-da-offset
B23: C0 | C23: llte_0_0_0_1_0_0 | D23: KHZ_30 | E23: 133 | F23: 2 | G23: llte_0_0_0_1_0_0 | H23: ru-pe.0 | I23: tac_0_0_0_1 | J23: llte_0_0_0_1_0_0 | K23: tac_0_0_0_1 | L23: 9 | M23: BFP | N23: 3900 | O23: 50000000 | P23: NR | Q23: 0 | R23: 19646 | T23: 6.8 | V23: =DEC2HEX(F23) | W23: 7
B24: C1 | C24: llte_0_0_1_1_0_0 | D24: KHZ_30 | E24: 133 | F24: 3 | G24: llte_0_0_1_1_0_0 | H24: ru-pe.0 | I24: tac_0_0_1_1 | J24: llte_0_0_1_1_0_0 | K24: tac_0_0_1_1 | L24: 9 | M24: BFP | N24: 3950 | O24: 50000000 | P24: NR | Q24: 0 | R24: 19646 | T24: 4.2 | V24: =DEC2HEX(F24) | W24: =W23
B25: C2 | C25: llte_0_1_0_2_0_0 | D25: KHZ_15 | E25: 106 | F25: 4 | G25: llte_0_1_0_2_0_0 | H25: ru-pe.0 | I25: tac_0_1_0_2 | J25: llte_0_1_0_2_0_0 | K25: tac_0_1_0_2 | L25: 9 | M25: BFP | N25: 1940 | O25: 20000000 | P25: NR | Q25: 0 | R25: 19646 | V25: =DEC2HEX(F25) | W25: =W24
B26: C3 | C26: llte_0_1_1_2_0_0 | D26: KHZ_15 | E26: 106 | F26: 5 | G26: llte_0_1_1_2_0_0 | H26: ru-pe.0 | I26: tac_0_1_1_2 | J26: llte_0_1_1_2_0_0 | K26: tac_0_1_1_2 | L26: 9 | M26: BFP | N26: 1960 | O26: 20000000 | P26: NR | Q26: 0 | R26: 19646 | V26: =DEC2HEX(F26) | W26: =W25
B27: C4 | C27: llte_0_2_0_3_0_0 | D27: KHZ_15 | E27: 25 | F27: 6 | G27: llte_0_2_0_3_0_0 | H27: ru-pe.0 | I27: tac_0_2_0_3 | J27: llte_0_2_0_3_0_0 | K27: tac_0_2_0_3 | L27: 9 | M27: BFP | N27: 864.5 | O27: 5000000 | P27: NR | Q27: 0 | R27: 19646 | V27: =DEC2HEX(F27) | W27: =W26 | AH27: UL Center
B28: C5 | C28: llte_0_2_1_3_0_0 | D28: KHZ_15 | E28: 25 | F28: 7 | G28: llte_0_2_1_3_0_0 | H28: ru-pe.0 | I28: tac_0_2_1_3 | J28: llte_0_2_1_3_0_0 | K28: tac_0_2_1_3 | L28: 9 | M28: BFP | N28: 869.5 | O28: 5000000 | P28: NR | Q28: 0 | R28: 19646 | V28: =DEC2HEX(F28) | W28: =W27 | AH28: 3900
B29: C6 | C29: llte_0_3_0_4_0_0 | D29: KHZ_15 | E29: 25 | F29: 8 | G29: llte_0_3_0_4_0_0 | H29: ru-pe.0 | I29: tac_0_3_0_4 | J29: llte_0_3_0_4_0_0 | K29: tac_0_3_0_4 | L29: 9 | M29: BFP | N29: 2352.5 | O29: 5000000 | P29: NR | Q29: 0 | R29: 19646 | V29: =DEC2HEX(F29) | W29: =W28
B30: C7 | C30: llte_0_3_1_4_0_0 | D30: KHZ_15 | E30: 25 | F30: 9 | G30: llte_0_3_1_4_0_0 | H30: ru-pe.0 | I30: tac_0_3_1_4 | J30: llte_0_3_1_4_0_0 | K30: tac_0_3_1_4 | L30: 9 | M30: BFP | N30: 2357.5 | O30: 5000000 | P30: NR | Q30: 0 | R30: 19646 | V30: =DEC2HEX(F30) | W30: =W29
C31: 고정 | F31: dec (oran은 hex로) | G31: 가능하나 고정 | H31: 가능하나 고정 | I31: 가능하나 고정 | J31: =C31 | K31: 가능하나 고정
B32: 4. PUSCH | S32: TC =~ 0.5 ns = 1/1.96608GHz
R33: =R36*R17 | S33: =S34*1000 | V33: =R34 | W33: =V33/1000 | X33: 10 | Y33: =X33-W33
C34: end-point | H34: link | N34: array-carrier | R34: =R33/1000 | S34: 100 | T34: 1.89 | U34: 4.09 | V34: =S34+R34 | W34: =V34/1000 | X34: 10 | Y34: =X34-W34
C35: name | D35: scs | E35: number-of-prb | F35: ul-fft-sampling-offset | G35: eaxc-id | H35: name | I35: processing-element | J35: rx-array-carrier | K35: low-level-rx-endpoint | L35: iq-bitwidth | M35: compression | N35: name | O35: Center-FREQ | P35: Channel-BW | Q35: type | R35: n-ta-offset | S35: T-au-offset | T35: Gain-Correction
B36: C0 | C36: llre_0_0_0_1_0_0 | D36: KHZ_15 | E36: 133 | F36: 0 | G36: 18 | H36: llre_0_0_0_1_0_0 | I36: ru-pe.0 | J36: rac_0_0_0_1 | K36: llre_0_0_0_1_0_0 | L36: 9 | M36: BFP | N36: rac_0_0_0_1 | O36: 3900 | P36: 50000000 | Q36: NR | R36: 25600 | S36: 19646 | T36: 0
B37: C1 | C37: llre_0_0_1_1_0_0 | D37: KHZ_15 | E37: 133 | F37: 0 | G37: 19 | H37: llre_0_0_1_1_0_0 | I37: ru-pe.0 | J37: rac_0_0_1_1 | K37: llre_0_0_1_1_0_0 | L37: 9 | M37: BFP | N37: rac_0_0_1_1 | O37: 3950 | P37: 50000000 | Q37: NR | R37: 25600 | S37: 19646 | T37: 0
B38: C2 | C38: llre_0_1_0_2_0_0 | D38: KHZ_15 | E38: 106 | F38: 0 | G38: 20 | H38: llre_0_1_0_2_0_0 | I38: ru-pe.0 | J38: rac_0_1_0_2 | K38: llre_0_1_0_2_0_0 | L38: 9 | M38: BFP | N38: rac_0_1_0_2 | O38: 1860 | P38: 20000000 | Q38: NR | R38: 25600 | S38: 19646 | T38: 0
B39: C3 | C39: llre_0_1_1_2_0_0 | D39: KHZ_15 | E39: 106 | F39: 0 | G39: 21 | H39: llre_0_1_1_2_0_0 | I39: ru-pe.0 | J39: rac_0_1_1_2 | K39: llre_0_1_1_2_0_0 | L39: 9 | M39: BFP | N39: rac_0_1_1_2 | O39: 1880 | P39: 20000000 | Q39: NR | R39: 25600 | S39: 19646 | T39: 0
B40: C4 | C40: llre_0_2_0_3_0_0 | D40: KHZ_15 | E40: 25 | F40: 0 | G40: 22 | H40: llre_0_2_0_3_0_0 | I40: ru-pe.0 | J40: rac_0_2_0_3 | K40: llre_0_2_0_3_0_0 | L40: 9 | M40: BFP | N40: rac_0_2_0_3 | O40: 832 | P40: 5000000 | Q40: NR | R40: 25600 | S40: 19646 | T40: 0
B41: C5 | C41: llre_0_2_1_3_0_0 | D41: KHZ_15 | E41: 25 | F41: 0 | G41: 23 | H41: llre_0_2_1_3_0_0 | I41: ru-pe.0 | J41: rac_0_2_1_3 | K41: llre_0_2_1_3_0_0 | L41: 9 | M41: BFP | N41: rac_0_2_1_3 | O41: 837 | P41: 5000000 | Q41: NR | R41: 25600 | S41: 19646 | T41: 0
B42: C6 | C42: llre_0_3_0_4_0_0 | D42: KHZ_15 | E42: 25 | F42: 0 | G42: 24 | H42: llre_0_3_0_4_0_0 | I42: ru-pe.0 | J42: rac_0_3_0_4 | K42: llre_0_3_0_4_0_0 | L42: 9 | M42: BFP | N42: rac_0_3_0_4 | O42: 2307.5 | P42: 5000000 | Q42: NR | R42: 25600 | S42: 19646 | T42: 0
B43: C7 | C43: llre_0_3_1_4_0_0 | D43: KHZ_15 | E43: 25 | F43: 0 | G43: 25 | H43: llre_0_3_1_4_0_0 | I43: ru-pe.0 | J43: rac_0_3_1_4 | K43: llre_0_3_1_4_0_0 | L43: 9 | M43: BFP | N43: rac_0_3_1_4 | O43: 2312.5 | P43: 5000000 | Q43: NR | R43: 25600 | S43: 19646 | T43: 0
C44: 고정 | H44: 가능하나 고정 | I44: 가능하나 고정 | J44: 가능하나 고정 | K44: =C44 | N44: 가능하나 고정
B45: 5. PRACH
...

Sheet CUplane-interface
A2: <rpc xmlns="urn:ietf:params:xml:ns:netconf:base:1.0" message-id="1">
A3: <edit-config>
A4: <target>
A5: <running/>
A6: </target>
A7: <default-operation>merge</default-operation>
A8: <config>
A9: <interfaces xmlns="urn:ietf:params:xml:ns:yang:ietf-interfaces">
A10: <interface>
A11: =" <name>"&'Control-Sheet'!D5&"</name>"
A12: <type xmlns:ianaift="urn:ietf:params:xml:ns:yang:iana-if-type">ianaift:l2vlan</type>
A13: =" <base-interface xmlns="&CHAR(34)&"urn:o-ran:interfaces:1.0"&CHAR(34)&">"&'Control-Sheet'!D6&"</base-interface>"
A14: =" <vlan-id xmlns="&CHAR(34)&"urn:o-ran:interfaces:1.0"&CHAR(34)&">"&'Control-Sheet'!D7&"</vlan-id>"
A15: =" <mac-address xmlns="&CHAR(34)&"urn:o-ran:interfaces:1.0"&CHAR(34)&">"&'Control-Sheet'!D8&"</mac-address>"
A16: <port-reference xmlns="urn:o-ran:interfaces:1.0">
A17: <port-number>0</port-number>
A18: </port-reference>
A19: </interface>
A20: </interfaces>
A21: </config>
A22: </edit-config>
A23: </rpc>

Sheet Processing-element
A1: <?xml version="1.0" encoding="UTF-8"?>
A2: <rpc xmlns="urn:ietf:params:xml:ns:netconf:base:1.0" message-id="1">
A3: <edit-config>
A4: <target>
A5: <running/>
A6: </target>
A7: <default-operation>merge</default-operation>
A8: <config>
A9: <processing-elements xmlns="urn:o-ran:processing-element:1.0">
A10: <transport-session-type>ETH-INTERFACE</transport-session-type>
A11: <ru-elements>
A12: =" <name>"&'Control-Sheet'!D13&"</name>"
A13: <transport-flow>
A14: =" <interface-name>"&'Control-Sheet'!D5&"</interface-name>"
A15: <eth-flow>
A16: =" <ru-mac-address>"&'Control-Sheet'!D8&"</ru-mac-address>"
A17: =" <vlan-id>"&'Control-Sheet'!D7&"</vlan-id>"
A18: =" <o-du-mac-address>"&'Control-Sheet'!D14&"</o-du-mac-address>"
A19: </eth-flow>
A20: </transport-flow>
A21: </ru-elements>
A22: </processing-elements>
A23: </config>
A24: </edit-config>
A25: </rpc>

Sheet PDSCH
A1: <?xml version="1.0" encoding="UTF-8"?>
A2: <rpc xmlns="urn:ietf:params:xml:ns:netconf:base:1.0" message-id="1">
A3: <edit-config>
A4: <target>
A5: <running/>
A6: </target>
A7: <default-operation>merge</default-operation>
A8: <config>
A9: <user-plane-configuration xmlns="urn:o-ran:uplane-conf:1.0">
A12: <low-level-tx-endpoints>
A13: =" <name>"&'Control-Sheet'!$C23&"</name>"
A14: <compression>
A15: <compression-type>STATIC</compression-type>
A16: =_xlfn.IFS('Control-Sheet'!M23="exponent", 'Control-Sheet'!$G$5, 'Control-Sheet'!M23="BFP", 'Control-Sheet'!$G$6, TRUE, "")
A17: =" <iq-bitwidth>"&'Control-Sheet'!L23&"</iq-bitwidth>"
A18: </compression>
A19: <frame-structure>160</frame-structure>
A20: <cp-type>NORMAL</cp-type>
A21: <cp-length>160</cp-length>
A22: <cp-length-other>144</cp-length-other>
A23: <offset-to-absolute-frequency-center>0</offset-to-absolute-frequency-center>
A24: <number-of-prb-per-scs>
A25: =" <scs>"&'Control-Sheet'!$D23&"</scs>"
A26: =" <number-of-prb>"&'Control-Sheet'!$E23&"</number-of-prb>"
A27: </number-of-prb-per-scs>
A28: <e-axcid>
A29: <o-du-port-bitmask>49152</o-du-port-bitmask>
A30: <band-sector-bitmask>12288</band-sector-bitmask>
A31: <ccid-bitmask>3840</ccid-bitmask>
A32: <ru-port-bitmask>255</ru-port-bitmask>
A33: =" <eaxc-id>"&'Control-Sheet'!$F23&"</eaxc-id>"
A34: </e-axcid>
A35: </low-level-tx-endpoints>
A36: <tx-array-carriers>
A37: =" <name>"&'Control-Sheet'!$K23&"</name>"
A38: <absolute-frequency-center>0</absolute-frequency-center>
A39: =" <center-of-channel-bandwidth>"&'Control-Sheet'!$N23*10^6&"</center-of-channel-bandwidth>"
A40: =" <channel-bandwidth>"&'Control-Sheet'!$O23*10^6&"</channel-bandwidth>"
A41: <active>INACTIVE</active>
A42: =" <type>"&'Control-Sheet'!$P23&"</type>"
...

Sheet PUSCH
A1: <?xml version="1.0" encoding="UTF-8"?>
A2: <rpc xmlns="urn:ietf:params:xml:ns:netconf:base:1.0" message-id="2">
A3: <edit-config>
A4: <target>
A5: <running/>
A6: </target>
A7: <default-operation>merge</default-operation>
A8: <config>
A9: <user-plane-configuration xmlns="urn:o-ran:uplane-conf:1.0">
A12: <low-level-rx-endpoints>
A13: =" <name>"&'Control-Sheet'!$C36&"</name>"
A14: <compression>
A15: <compression-type>STATIC</compression-type>
A16: =_xlfn.IFS('Control-Sheet'!M36="exponent", 'Control-Sheet'!$G$5, 'Control-Sheet'!M36="BFP", 'Control-Sheet'!$G$6, TRUE, "")
A17: =" <iq-bitwidth>"&'Control-Sheet'!L36&"</iq-bitwidth>"
A18: </compression>
A19: <frame-structure>160</frame-structure>
A20: <cp-type>NORMAL</cp-type>
A21: <cp-length>160</cp-length>
A22: <cp-length-other>144</cp-length-other>
A23: <offset-to-absolute-frequency-center>0</offset-to-absolute-frequency-center>
A24: <number-of-prb-per-scs>
A25: =" <scs>"&'Control-Sheet'!$D36&"</scs>"
A26: =" <number-of-prb>"&'Control-Sheet'!$E36&"</number-of-prb>"
A27: </number-of-prb-per-scs>
A28: <ul-fft-sampling-offsets>
A29: =" <scs>"&'Control-Sheet'!$D36&"</scs>"
A30: =" <ul-fft-sampling-offset>"&'Control-Sheet'!$F36&"</ul-fft-sampling-offset>"
A31: </ul-fft-sampling-offsets>
A32: <e-axcid>
A33: <o-du-port-bitmask>49152</o-du-port-bitmask>
A34: <band-sector-bitmask>12288</band-sector-bitmask>
A35: <ccid-bitmask>3840</ccid-bitmask>
A36: <ru-port-bitmask>255</ru-port-bitmask>
A37: =" <eaxc-id>"&'Control-Sheet'!$G36&"</eaxc-id>"
A38: </e-axcid>
A39: </low-level-rx-endpoints>
A40: <rx-array-carriers>
A41: =" <name>"&'Control-Sheet'!$N36&"</name>"
A42: <absolute-frequency-center>0</absolute-frequency-center>
...

Sheet PRACH
A1: <?xml version="1.0" encoding="UTF-8"?>
A2: <rpc xmlns="urn:ietf:params:xml:ns:netconf:base:1.0" message-id="1">
A3: <edit-config>
A4: <target>
A5: <running/>
A6: </target>
A7: <default-operation>merge</default-operation>
A8: <config>
A9: <user-plane-configuration xmlns="urn:o-ran:uplane-conf:1.0">
A12: <low-level-rx-endpoints>
A13: =" <name>"&'Control-Sheet'!$C49&"</name>"
A14: <compression>
A15: <compression-type>STATIC</compression-type>
A16: =_xlfn.IFS('Control-Sheet'!M49="exponent", 'Control-Sheet'!$G$5, 'Control-Sheet'!M49="BFP", 'Control-Sheet'!$G$6, TRUE, "")
A17: =" <iq-bitwidth>"&'Control-Sheet'!L49&"</iq-bitwidth>"
A18: </compression>
A19: <frame-structure>160</frame-structure>
A20: <cp-type>NORMAL</cp-type>
A21: <cp-length>160</cp-length>
A22: <cp-length-other>144</cp-length-other>
A23: <offset-to-absolute-frequency-center>0</offset-to-absolute-frequency-center>
A24: <number-of-prb-per-scs>
A25: =" <scs>"&'Control-Sheet'!$D49&"</scs>"
A26: =" <number-of-prb>"&'Control-Sheet'!$E49&"</number-of-prb>"
A27: </number-of-prb-per-scs>
A28: <ul-fft-sampling-offsets>
A29: =" <scs>"&'Control-Sheet'!$D49&"</scs>"
A30: =" <ul-fft-sampling-offset>"&'Control-Sheet'!$F49&"</ul-fft-sampling-offset>"
A31: </ul-fft-sampling-offsets>
A32: <e-axcid>
A33: <o-du-port-bitmask>49152</o-du-port-bitmask>
A34: <band-sector-bitmask>12288</band-sector-bitmask>
A35: <ccid-bitmask>3840</ccid-bitmask>
A36: <ru-port-bitmask>255</ru-port-bitmask>
A37: =" <eaxc-id>"&'Control-Sheet'!$G49&"</eaxc-id>"
A38: </e-axcid>
A39: </low-level-rx-endpoints>
A40: <low-level-rx-links>
A41: =" <name>"&'Control-Sheet'!$H49&"</name>"
A42: =" <processing-element>"&'Control-Sheet'!$I49&"</processing-element>"
...

Sheet ACTIVE
A1: <rpc message-id="30" xmlns="urn:ietf:params:xml:ns:netconf:base:1.0">
A2: <edit-config>
A3: <target>
A4: <running/>
A5: </target>
A6: <config>
A7: <user-plane-configuration xmlns="urn:o-ran:uplane-conf:1.0">
A10: <tx-array-carriers>
A11: =" <name>"&'Control-Sheet'!$K23&"</name>"
A12: <active>ACTIVE</active>
A13: </tx-array-carriers>
A14: <tx-array-carriers>
A15: =" <name>"&'Control-Sheet'!$K24&"</name>"
A16: <active>ACTIVE</active>
A17: </tx-array-carriers>
A20: <tx-array-carriers>
A21: =" <name>"&'Control-Sheet'!$K25&"</name>"
A22: <active>ACTIVE</active>
A23: </tx-array-carriers>
A24: <tx-array-carriers>
A25: =" <name>"&'Control-Sheet'!$K26&"</name>"
A26: <active>ACTIVE</active>
A27: </tx-array-carriers>
A30: <tx-array-carriers>
A31: =" <name>"&'Control-Sheet'!$K27&"</name>"
A32: <active>ACTIVE</active>
A33: </tx-array-carriers>
A34: <tx-array-carriers>
A35: =" <name>"&'Control-Sheet'!$K28&"</name>"
A36: <active>ACTIVE</active>
A37: </tx-array-carriers>
A40: <tx-array-carriers>
A41: =" <name>"&'Control-Sheet'!$K29&"</name>"
A42: <active>ACTIVE</active>
A43: </tx-array-carriers>
A44: <tx-array-carriers>
A45: =" <name>"&'Control-Sheet'!$K30&"</name>"
A46: <active>ACTIVE</active>
A47: </tx-array-carriers>
A50: <rx-array-carriers>
...
