Workbook

Sheet Control-Sheet
B3: 1. Cuplane-interface | O3: NR | Q3: LTE
G4: 삭제 금지 | N4: BW | O4: KHZ_15 | P4: KHZ_30 | Q4: KHZ_15
C5: name | D5: DLPU_DSD1 | E5: VLAN NAME | G5: <exponent>4</exponent> | K5: <!-- | N5: 5 | O5: 25 | P5: 11 | Q5: 25
C6: Base-interface | D6: sys | E6: 고정 | G6: <compression-method>BLOCK_FLOATING_POINT</compression-method> | K6: --> | N6: 10 | O6: 52 | P6: 24 | Q6: 50
C7: vlan id | D7: 1000 | N7: 15 | O7: 79 | P7: 38 | Q7: 75
C8: ORU mac-address | D8: 00:0a:35:00:00:02 | E8: nDLPU MAC | N8: 20 | O8: 106 | P8: 51 | Q8: 100
N9: 25 | O9: 216 | P9: 65
N10: 30 | O10: 270 | P10: 78
B11: 2. Processing element | N11: 40 | P11: 106
N12: 50 | P12: 133
C13: name | D13: ru-pe.0 | E13: oran player | N13: 60 | P13: 162
C14: ODU mac-address | D14: 80:09:02:03:04:05 | E14: 변경 가능 고정 사용 | N14: 80 | P14: 217
N15: 90 | P15: 245
B16: 2-1. 해당 주파수 | N16: 100 | P16: 273
B17: CASE#1 | C17: 8cc
B18: 주석(ON/OFF) | C18: cc | D18: ant# | E18: SCS | F18: number-of-prb | G18: iq-bitwidth | H18: compression | I18: type | J18: DL Center | K18: BW | L18: UL Center | M18: Gain | N18: External Delay(us)
B19: OFF | C19: 0 | D19: 1 | E19: 30 | F19: 133 | G19: 9 | H19: BFP | I19: NR | J19: 3900 | K19: 50 | L19: 3900 | M19: 0 | N19: 0
B20: ON | C20: 1 | D20: 2 | E20: 15 | F20: 106 | G20: 9 | I20: NR | J20: 1940 | K20: 20 | L20: 1860 | M20: 0
B21: OFF | C21: 2 | D21: 3 | E21: 15 | F21: 25 | G21: 9 | I21: NR | J21: 864.5 | K21: 5 | L21: 832 | M21: 0
B22: OFF | C22: 3 | D22: 4 | E22: 15 | F22: 25 | G22: 9 | I22: NR | J22: 2352.5 | K22: 5 | L22: 2307.5 | M22: 0
R23: 0.509
R24: Tc = 1 / (480kHz · 4096) = 0.509 ns
B25: 3. PDSCH | R25: TC =~ 0.5 ns = 1/1.96608GHz | W25: <exponent>4<exponent>
R26: 10000
C27: end-point | G27: link | K27: array-carrier | R27: 100 | S27: 6.81
C28: name | D28: scs | E28: number-of-prb | F28: eaxc-id | G28: name | H28: processing-element | I28: rx-array-carrier | J28: low-level-rx-endpoint | K28: name | L28: iq-bitwidth | M28: compression | N28: Center-FREQ | O28: Channel-BW | P28: type | Q28: gain | R28: T-da-offset
B29: C0 | C29: ="llte_0_" & MID(C19, 1, 1)&"_0_1_0_0" | D29: ="KHZ_" & MID(E19, 1, 2) | E29: =F19 | F29: 2 | G29: ="lltl_" & MID(C29, 6, 11) | H29: =$D$13 | I29: ="tac_" & MID(C29, 6, 7) | J29: =C29 | K29: =I29 | L29: =$G$19 | M29: =$H$19 | N29: =J19 | O29: =K19 | P29: =I19 | Q29: =$M$19 | R29: =ROUND($R$26/$R$23,0.1) | T29: 6.8 | V29: =DEC2HEX(F29) | W29: 7
B30: C1 | C30: ="llte_0_" & MID(C19, 1, 1)&"_1_1_0_0" | D30: =D29 | E30: =E29 | F30: 3 | G30: ="lltl_" & MID(C30, 6, 11) | H30: =$D$13 | I30: ="tac_" & MID(C30, 6, 7) | J30: =C30 | K30: =I30 | L30: =L29 | M30: =$H$19 | N30: =J19+K19 | O30: =O29 | P30: =P29 | Q30: =$M$19 | R30: =ROUND($R$26/$R$23,0.1) | T30: 4.2 | V30: =DEC2HEX(F30) | W30: =W29
B31: C2 | C31: ="llte_0_" & MID(C20, 1, 1)&"_0_2_0_0" | D31: ="KHZ_" & MID(E20, 1, 2) | E31: =F20 | F31: 4 | G31: ="lltl_" & MID(C31, 6, 11) | H31: =$D$13 | I31: ="tac_" & MID(C31, 6, 7) | J31: =C31 | K31: =I31 | L31: =$G$20 | M31: =$H$19 | N31: =J20 | O31: =K20 | P31: =I20 | Q31: =$M$20 | R31: =ROUND($R$26/$R$23,0.1) | V31: =DEC2HEX(F31) | W31: =W30
B32: C3 | C32: ="llte_0_" & MID(C20, 1, 1)&"_1_2_0_0" | D32: =D31 | E32: =E31 | F32: 5 | G32: ="lltl_" & MID(C32, 6, 11) | H32: =$D$13 | I32: ="tac_" & MID(C32, 6, 7) | J32: =C32 | K32: =I32 | L32: =L31 | M32: =$H$19 | N32: =N31+O31 | O32: =O31 | P32: =P31 | Q32: =$M$20 | R32: =ROUND($R$26/$R$23,0.1) | V32: =DEC2HEX(F32) | W32: =W31
B33: C4 | C33: ="llte_0_" & MID(C21, 1, 1)&"_0_3_0_0" | D33: ="KHZ_" & MID(E21, 1, 2) | E33: =F21 | F33: 6 | G33: ="lltl_" & MID(C33, 6, 11) | H33: =$D$13 | I33: ="tac_" & MID(C33, 6, 7) | J33: =C33 | K33: =I33 | L33: =$G$21 | M33: =$H$19 | N33: =J21 | O33: =K21 | P33: =I21 | Q33: =$M$21 | R33: =ROUND($R$26/$R$23,0.1) | V33: =DEC2HEX(F33) | W33: =W32 | AH33: UL Center
B34: C5 | C34: ="llte_0_" & MID(C21, 1, 1)&"_1_3_0_0" | D34: =D33 | E34: =E33 | F34: 7 | G34: ="lltl_" & MID(C34, 6, 11) | H34: =$D$13 | I34: ="tac_" & MID(C34, 6, 7) | J34: =C34 | K34: =I34 | L34: =L33 | M34: =$H$19 | N34: =N33+O33 | O34: =O33 | P34: =P33 | Q34: =$M$21 | R34: =ROUND($R$26/$R$23,0.1) | V34: =DEC2HEX(F34) | W34: =W33 | AH34: 3900
B35: C6 | C35: ="llte_0_" & MID(C22, 1, 1)&"_0_4_0_0" | D35: ="KHZ_" & MID(E22, 1, 2) | E35: =F22 | F35: 8 | G35: ="lltl_" & MID(C35, 6, 11) | H35: =$D$13 | I35: ="tac_" & MID(C35, 6, 7) | J35: =C35 | K35: =I35 | L35: =$G$22 | M35: =$H$19 | N35: =J22 | O35: =K22 | P35: =I22 | Q35: =$M$22 | R35: =ROUND($R$26/$R$23,0.1) | V35: =DEC2HEX(F35) | W35: =W34
B36: C7 | C36: ="llte_0_" & MID(C22, 1, 1)&"_1_4_0_0" | D36: =D35 | E36: =E35 | F36: 9 | G36: ="lltl_" & MID(C36, 6, 11) | H36: =$D$13 | I36: ="tac_" & MID(C36, 6, 7) | J36: =C36 | K36: =I36 | L36: =L35 | M36: =$H$19 | N36: =N35+O35 | O36: =O35 | P36: =P35 | Q36: =$M$22 | R36: =ROUND($R$26/$R$23,0.1) | V36: =DEC2HEX(F36) | W36: =W35
C37: 고정 | F37: dec (oran은 hex로) | G37: 가능하나 고정 | H37: 가능하나 고정 | I37: 가능하나 고정 | J37: =C37 | K37: 가능하나 고정
B38: 4. PUSCH | S38: TC =~ 0.5 ns = 1/1.96608GHz
R39: =R42*R23 | S39: =S40*1000 | V39: =R40 | W39: =V39/1000 | X39: 10 | Y39: =X39-W39
C40: end-point | H40: link | N40: array-carrier | R40: =R39/1000 | S40: 100 | T40: 1.89 | U40: 4.09 | V40: =S40+R40 | W40: =V40/1000 | X40: 10 | Y40: =X40-W40
C41: name | D41: scs | E41: number-of-prb | F41: ul-fft-sampling-offset | G41: eaxc-id | H41: name | I41: processing-element | J41: rx-array-carrier | K41: low-level-rx-endpoint | L41: iq-bitwidth | M41: compression | N41: name | O41: Center-FREQ | P41: Channel-BW | Q41: type | R41: n-ta-offset | S41: T-au-offset | T41: Gain-Correction
B42: C0 | C42: ="llre_" & MID(C29, 6, 11) | D42: =D29 | E42: =E29 | F42: 0 | G42: 18 | H42: ="llrl_" & MID(C42, 6, 11) | I42: =$D$13 | J42: ="rac_" & MID(C42, 6, 7) | K42: =C42 | L42: =$G$19 | M42: =$H$19 | N42: =J42 | O42: =L19 | P42: =O29 | Q42: =P29 | R42: 25600 | S42: =ROUND($R$26/$R$23,0.1) | T42: 0 | V42: =DEC2HEX(G42)
...

Sheet CUplane-interface
A2: <rpc xmlns="urn:ietf:params:xml:ns:netconf:base:1.0" message-id="1">
A3: <edit-config>
A4: <target>
A5: <running/>
A6: </target>
A7: <default-operation>merge</default-operation>
A8: <config>
A9: <interfaces xmlns="urn:ietf:params:xml:ns:yang:ietf-interfaces">
A10: <interface>
A11: =" <name>"&'Control-Sheet'!D5&"</name>"
A12: <type xmlns:ianaift="urn:ietf:params:xml:ns:yang:iana-if-type">ianaift:l2vlan</type>
A13: =" <base-interface xmlns="&CHAR(34)&"urn:o-ran:interfaces:1.0"&CHAR(34)&">"&'Control-Sheet'!D6&"</base-interface>"
A14: =" <vlan-id xmlns="&CHAR(34)&"urn:o-ran:interfaces:1.0"&CHAR(34)&">"&'Control-Sheet'!D7&"</vlan-id>"
A15: =" <mac-address xmlns="&CHAR(34)&"urn:o-ran:interfaces:1.0"&CHAR(34)&">"&'Control-Sheet'!D8&"</mac-address>"
A16: <port-reference xmlns="urn:o-ran:interfaces:1.0">
A17: <port-number>0</port-number>
A18: </port-reference>
A19: </interface>
A20: </interfaces>
A21: </config>
A22: </edit-config>
A23: </rpc>

Sheet Processing-element
A1: <?xml version="1.0" encoding="UTF-8"?>
A2: <rpc xmlns="urn:ietf:params:xml:ns:netconf:base:1.0" message-id="1">
A3: <edit-config>
A4: <target>
A5: <running/>
A6: </target>
A7: <default-operation>merge</default-operation>
A8: <config>
A9: <processing-elements xmlns="urn:o-ran:processing-element:1.0">
A10: <transport-session-type>ETH-INTERFACE</transport-session-type>
A11: <ru-elements>
A12: =" <name>"&'Control-Sheet'!D13&"</name>"
A13: <transport-flow>
A14: =" <interface-name>"&'Control-Sheet'!D5&"</interface-name>"
A15: <eth-flow>
A16: =" <ru-mac-address>"&'Control-Sheet'!D8&"</ru-mac-address>"
A17: =" <vlan-id>"&'Control-Sheet'!D7&"</vlan-id>"
A18: =" <o-du-mac-address>"&'Control-Sheet'!D14&"</o-du-mac-address>"
A19: </eth-flow>
A20: </transport-flow>
A21: </ru-elements>
A22: </processing-elements>
A23: </config>
A24: </edit-config>
A25: </rpc>

Sheet PDSCH
A1: <?xml version="1.0" encoding="UTF-8"?>
A2: <rpc xmlns="urn:ietf:params:xml:ns:netconf:base:1.0" message-id="1">
A3: <edit-config>
A4: <target>
A5: <running/>
A6: </target>
A7: <default-operation>merge</default-operation>
A8: <config>
A9: <user-plane-configuration xmlns="urn:o-ran:uplane-conf:1.0">
A11: =_xlfn.IFS('Control-Sheet'!B19="OFF", 'Control-Sheet'!$K$5, TRUE, "")
A12: <low-level-tx-endpoints>
A13: =" <name>"&'Control-Sheet'!$C29&"</name>"
A14: <compression>
A15: <compression-type>STATIC</compression-type>
A16: =_xlfn.IFS('Control-Sheet'!M29="exponent", 'Control-Sheet'!$G$5, 'Control-Sheet'!M29="BFP", 'Control-Sheet'!$G$6, TRUE, "")
A17: =" <iq-bitwidth>"&'Control-Sheet'!L29&"</iq-bitwidth>"
A18: </compression>
A19: <frame-structure>160</frame-structure>
A20: <cp-type>NORMAL</cp-type>
A21: <cp-length>160</cp-length>
A22: <cp-length-other>144</cp-length-other>
A23: <offset-to-absolute-frequency-center>0</offset-to-absolute-frequency-center>
A24: <number-of-prb-per-scs>
A25: =" <scs>"&'Control-Sheet'!$D29&"</scs>"
A26: =" <number-of-prb>"&'Control-Sheet'!$E29&"</number-of-prb>"
A27: </number-of-prb-per-scs>
A28: <e-axcid>
A29: <o-du-port-bitmask>49152</o-du-port-bitmask>
A30: <band-sector-bitmask>12288</band-sector-bitmask>
A31: <ccid-bitmask>3840</ccid-bitmask>
A32: <ru-port-bitmask>255</ru-port-bitmask>
A33: =" <eaxc-id>"&'Control-Sheet'!$F29&"</eaxc-id>"
A34: </e-axcid>
A35: </low-level-tx-endpoints>
A36: <tx-array-carriers>
A37: =" <name>"&'Control-Sheet'!$K29&"</name>"
A38: <absolute-frequency-center>0</absolute-frequency-center>
A39: =" <center-of-channel-bandwidth>"&'Control-Sheet'!$N29*10^6&"</center-of-channel-bandwidth>"
A40: =" <channel-bandwidth>"&'Control-Sheet'!$O29*10^6&"</channel-bandwidth>"
A41: <active>INACTIVE</active>
...

Sheet PUSCH
A1: <?xml version="1.0" encoding="UTF-8"?>
A2: <rpc xmlns="urn:ietf:params:xml:ns:netconf:base:1.0" message-id="2">
A3: <edit-config>
A4: <target>
A5: <running/>
A6: </target>
A7: <default-operation>merge</default-operation>
A8: <config>
A9: <user-plane-configuration xmlns="urn:o-ran:uplane-conf:1.0">
A11: =_xlfn.IFS('Control-Sheet'!B19="OFF", 'Control-Sheet'!$K$5, TRUE, "")
A12: <low-level-rx-endpoints>
A13: =" <name>"&'Control-Sheet'!$C42&"</name>"
A14: <compression>
A15: <compression-type>STATIC</compression-type>
A16: =_xlfn.IFS('Control-Sheet'!M42="exponent", 'Control-Sheet'!$G$5, 'Control-Sheet'!M42="BFP", 'Control-Sheet'!$G$6, TRUE, "")
A17: =" <iq-bitwidth>"&'Control-Sheet'!L42&"</iq-bitwidth>"
A18: </compression>
A19: <frame-structure>160</frame-structure>
A20: <cp-type>NORMAL</cp-type>
A21: <cp-length>160</cp-length>
A22: <cp-length-other>144</cp-length-other>
A23: <offset-to-absolute-frequency-center>0</offset-to-absolute-frequency-center>
A24: <number-of-prb-per-scs>
A25: =" <scs>"&'Control-Sheet'!$D42&"</scs>"
A26: =" <number-of-prb>"&'Control-Sheet'!$E42&"</number-of-prb>"
A27: </number-of-prb-per-scs>
A28: <ul-fft-sampling-offsets>
A29: =" <scs>"&'Control-Sheet'!$D42&"</scs>"
A30: =" <ul-fft-sampling-offset>"&'Control-Sheet'!$F42&"</ul-fft-sampling-offset>"
A31: </ul-fft-sampling-offsets>
A32: <e-axcid>
A33: <o-du-port-bitmask>49152</o-du-port-bitmask>
A34: <band-sector-bitmask>12288</band-sector-bitmask>
A35: <ccid-bitmask>3840</ccid-bitmask>
A36: <ru-port-bitmask>255</ru-port-bitmask>
A37: =" <eaxc-id>"&'Control-Sheet'!$G42&"</eaxc-id>"
A38: </e-axcid>
A39: </low-level-rx-endpoints>
A40: <rx-array-carriers>
A41: =" <name>"&'Control-Sheet'!$N42&"</name>"
...

Sheet PRACH
A1: <?xml version="1.0" encoding="UTF-8"?>
A2: <rpc xmlns="urn:ietf:params:xml:ns:netconf:base:1.0" message-id="1">
A3: <edit-config>
A4: <target>
A5: <running/>
A6: </target>
A7: <default-operation>merge</default-operation>
A8: <config>
A9: <user-plane-configuration xmlns="urn:o-ran:uplane-conf:1.0">
A11: =_xlfn.IFS('Control-Sheet'!B19="OFF", 'Control-Sheet'!$K$5, TRUE, "")
A12: <low-level-rx-endpoints>
A13: =" <name>"&'Control-Sheet'!$C55&"</name>"
A14: <compression>
A15: <compression-type>STATIC</compression-type>
A16: =_xlfn.IFS('Control-Sheet'!M55="exponent", 'Control-Sheet'!$G$5, 'Control-Sheet'!M55="BFP", 'Control-Sheet'!$G$6, TRUE, "")
A17: =" <iq-bitwidth>"&'Control-Sheet'!L55&"</iq-bitwidth>"
A18: </compression>
A19: <frame-structure>160</frame-structure>
A20: <cp-type>NORMAL</cp-type>
A21: <cp-length>160</cp-length>
A22: <cp-length-other>144</cp-length-other>
A23: <offset-to-absolute-frequency-center>0</offset-to-absolute-frequency-center>
A24: <number-of-prb-per-scs>
A25: =" <scs>"&'Control-Sheet'!$D55&"</scs>"
A26: =" <number-of-prb>"&'Control-Sheet'!$E55&"</number-of-prb>"
A27: </number-of-prb-per-scs>
A28: <ul-fft-sampling-offsets>
A29: =" <scs>"&'Control-Sheet'!$D55&"</scs>"
A30: =" <ul-fft-sampling-offset>"&'Control-Sheet'!$F55&"</ul-fft-sampling-offset>"
A31: </ul-fft-sampling-offsets>
A32: <e-axcid>
A33: <o-du-port-bitmask>49152</o-du-port-bitmask>
A34: <band-sector-bitmask>12288</band-sector-bitmask>
A35: <ccid-bitmask>3840</ccid-bitmask>
A36: <ru-port-bitmask>255</ru-port-bitmask>
A37: =" <eaxc-id>"&'Control-Sheet'!$G55&"</eaxc-id>"
A38: </e-axcid>
A39: </low-level-rx-endpoints>
A40: <low-level-rx-links>
A41: =" <name>"&'Control-Sheet'!$H55&"</name>"
...

Sheet ACTIVE
A1: <rpc message-id="30" xmlns="urn:ietf:params:xml:ns:netconf:base:1.0">
A2: <edit-config>
A3: <target>
A4: <running/>
A5: </target>
A6: <config>
A7: <user-plane-configuration xmlns="urn:o-ran:uplane-conf:1.0">
A9: =_xlfn.IFS('Control-Sheet'!B19="OFF", 'Control-Sheet'!$K$5, TRUE, "")
A10: <tx-array-carriers>
A11: =" <name>"&'Control-Sheet'!$K29&"</name>"
A12: <active>ACTIVE</active>
A13: </tx-array-carriers>
A14: <tx-array-carriers>
A15: =" <name>"&'Control-Sheet'!$K30&"</name>"
A16: <active>ACTIVE</active>
A17: </tx-array-carriers>
A18: =_xlfn.IFS('Control-Sheet'!B19="OFF", 'Control-Sheet'!$K$6, TRUE, "")
A19: =_xlfn.IFS('Control-Sheet'!B20="OFF", 'Control-Sheet'!$K$5, TRUE, "")
A20: <tx-array-carriers>
A21: =" <name>"&'Control-Sheet'!$K31&"</name>"
A22: <active>ACTIVE</active>
A23: </tx-array-carriers>
A24: <tx-array-carriers>
A25: =" <name>"&'Control-Sheet'!$K32&"</name>"
A26: <active>ACTIVE</active>
A27: </tx-array-carriers>
A28: =_xlfn.IFS('Control-Sheet'!B20="OFF", 'Control-Sheet'!$K$6, TRUE, "")
A29: =_xlfn.IFS('Control-Sheet'!B21="OFF", 'Control-Sheet'!$K$5, TRUE, "")
A30: <tx-array-carriers>
A31: =" <name>"&'Control-Sheet'!$K33&"</name>"
A32: <active>ACTIVE</active>
A33: </tx-array-carriers>
A34: <tx-array-carriers>
A35: =" <name>"&'Control-Sheet'!$K34&"</name>"
A36: <active>ACTIVE</active>
A37: </tx-array-carriers>
A38: =_xlfn.IFS('Control-Sheet'!B21="OFF", 'Control-Sheet'!$K$6, TRUE, "")
A39: =_xlfn.IFS('Control-Sheet'!B22="OFF", 'Control-Sheet'!$K$5, TRUE, "")
A40: <tx-array-carriers>
A41: =" <name>"&'Control-Sheet'!$K35&"</name>"
...

Sheet LLTE,LLRE
F6: Interface | G6: Band/Sector | H6: CC | I6: Spatial stream | J6: PUxCH&PRACH
E7: low-level-tx-endpoint | F7: 0 | G7: 0 | H7: 0 | I7: 1 | J7: 0 | K7: 0
F8: 0 | G8: 0 | H8: 1 | I8: 1 | J8: 0 | K8: 0
E9: low-level-rx-endpoint

Sheet RSRP_EffBW
E38: RSRP offset | F38: measured RSRP | H38: RSRQ | M38: BW(kHz) | N38: symbols | O38: SCS | P38: No of RB | Q38: Effective BW | R38: % | S38: Guardband | T38: Eg to Eg | V38: D filter
B39: BW | C39: SCS | D39: RB | E39: Referance power offset | F39: measured reference power | G39: RSSI | L39: NR | M39: 5000 | N39: 12 | O39: 15 | P39: 25 | Q39: =P39*O39*N39 | R39: =Q39/M39 | S39: =(M39-P39*O39*N39)/2-O39/2 | T39: =S39*2 | U39: -> | V39: 450 | W39: ?
B40: 20 | C40: 30 | D40: 51 | E40: =10*LOG(12*D40) | F40: -15 | G40: =F40-(-E40) | H40: =10*LOG(D40)+F40-G40 | M40: =M39 | N40: 12 | O40: 30 | P40: 11 | Q40: =P40*O40*N40 | R40: =Q40/M40 | S40: =(M40-P40*O40*N40)/2-O40/2 | T40: =S40*2 | U40: -> | V40: 1000 | W40: ?
B41: 20 | C41: 15 | D41: 106 | E41: =10*LOG(12*D41) | F41: -15 | G41: =F41-(-E41) | H41: =10*LOG(D41)+F41-G41 | L41: LTE | M41: =M39 | N41: 12 | O41: 15 | P41: 25 | Q41: =P41*O41*N41 | R41: =Q41/M41 | S41: =(M41-P41*O41*N41)/2-O41/2 | T41: =S41*2 | U41: -> | V41: 450 | W41: ?
C43: 84 | D43: 14 | E43: =C43/D43 | L43: NR | M43: 20000 | N43: 12 | O43: 15 | P43: 106 | Q43: =P43*O43*N43 | R43: =Q43/M43 | S43: =(M43-P43*O43*N43)/2-O43/2 | T43: =S43*2 | U43: -> | V43: 900 | W43: ?
M44: =M43 | N44: 12 | O44: 30 | P44: 51 | Q44: =P44*O44*N44 | R44: =Q44/M44 | S44: =(M44-P44*O44*N44)/2-O44/2 | T44: =S44*2
B45: 100 | C45: 30 | D45: 273 | E45: =10*LOG(12*D45) | F45: -22.8 | G45: =F45-(-E45) | H45: =10*LOG(D45)+F45-G45 | L45: LTE | M45: =M43 | N45: 12 | O45: 15 | P45: 100 | Q45: =P45*O45*N45 | R45: =Q45/M45 | S45: =(M45-P45*O45*N45)/2-O45/2 | T45: =S45*2
D46: =10^(E46/10)/12 | E46: =G46-F46 | F46: -22.8 | G46: 0.31
D47: 17 | E47: =10*LOG(12*D47) | F47: -22.87 | G47: =E47+F47-H47 | H47: -10.167 | I47: =G47-F47-H47 | L47: NR | M47: 40000 | N47: 12 | O47: 15 | P47: 216 | Q47: =P47*O47*N47 | R47: =Q47/M47 | S47: =(M47-P47*O47*N47)/2-O47/2 | T47: =S47*2 | U47: -> | V47: =ROUND(T47,0.001) | W47: ?
M48: =M47 | N48: 12 | O48: 30 | P48: 106 | Q48: =P48*O48*N48 | R48: =Q48/M48 | S48: =(M48-P48*O48*N48)/2-O48/2 | T48: =S48*2
D49: S-SS RB수
B50: 100 | C50: 30 | D50: 20 | E50: =10*LOG(12*D50) | F50: -22.87 | G50: =F50-(-E50) | H50: =10*LOG(D50)+F50-G50 | L50: NR | M50: 100000 | N50: 12 | O50: 30 | P50: 273 | Q50: =P50*O50*N50 | R50: =Q50/M50 | S50: =(M50-P50*O50*N50)/2-O50/2 | T50: =S50*2 | U50: -> | V50: 1400 | W50: 60
V51: 900 | W51: 17
V52: 400 | W52: 3
M55: BW(kHz) | N55: symbols | O55: SCS | P55: No of RB | Q55: Effective BW | R55: % | S55: Guardband | T55: Eg to Eg
L56: NR | M56: 5000 | N56: 12 | O56: 15 | P56: 25 | Q56: =P56*O56*N56 | R56: =Q56/M56 | S56: =(M56-P56*O56*N56)/2-O56/2 | T56: =S56*2
M57: =M56 | N57: 12 | O57: 30 | P57: 11 | Q57: =P57*O57*N57 | R57: =Q57/M57 | S57: =(M57-P57*O57*N57)/2-O57/2 | T57: =S57*2
L58: LTE | M58: =M56 | N58: 12 | O58: 15 | P58: 25 | Q58: =P58*O58*N58 | R58: =Q58/M58 | S58: =(M58-P58*O58*N58)/2-O58/2 | T58: =S58*2
L60: NR | M60: 10000 | N60: 12 | O60: 15 | P60: 52 | Q60: =P60*O60*N60 | R60: =Q60/M60 | S60: =(M60-P60*O60*N60)/2-O60/2 | T60: =S60*2
M61: =M60 | N61: 12 | O61: 30 | P61: 24 | Q61: =P61*O61*N61 | R61: =Q61/M61 | S61: =(M61-P61*O61*N61)/2-O61/2 | T61: =S61*2
L62: LTE | M62: =M60 | N62: 12 | O62: 15 | P62: 50 | Q62: =P62*O62*N62 | R62: =Q62/M62 | S62: =(M62-P62*O62*N62)/2-O62/2 | T62: =S62*2
L64: NR | M64: 20000 | N64: 12 | O64: 15 | P64: 106 | Q64: =P64*O64*N64 | R64: =Q64/M64 | S64: =(M64-P64*O64*N64)/2-O64/2 | T64: =S64*2 | W64: @ | X64: ATTEN
M65: =M64 | N65: 12 | O65: 30 | P65: 51 | Q65: =P65*O65*N65 | R65: =Q65/M65 | S65: =(M65-P65*O65*N65)/2-O65/2 | T65: =S65*2 | V65: windowing filter | W65: 400 | X65: 3
L66: LTE | M66: =M64 | N66: 12 | O66: 15 | P66: 100 | Q66: =P66*O66*N66 | R66: =Q66/M66 | S66: =(M66-P66*O66*N66)/2-O66/2 | T66: =S66*2 | W66: 900 | X66: 17
W67: 1400 | X67: 60
L68: NR | M68: 40000 | N68: 12 | O68: 15 | P68: 216 | Q68: =P68*O68*N68 | R68: =Q68/M68 | S68: =(M68-P68*O68*N68)/2-O68/2 | T68: =S68*2
M69: =M68 | N69: 12 | O69: 30 | P69: 106 | Q69: =P69*O69*N69 | R69: =Q69/M69 | S69: =(M69-P69*O69*N69)/2-O69/2 | T69: =S69*2
L71: NR | M71: 100000 | N71: 12 | O71: 30 | P71: 273 | Q71: =P71*O71*N71 | R71: =Q71/M71 | S71: =(M71-P71*O71*N71)/2-O71/2 | T71: =S71*2
