Workbook

Sheet Control-Sheet
B2: 1. Cuplane-interface
C4: name | D4: 1000
C5: Base-interface | D5: sys
C6: vlan id | D6: 1000
C7: ORU mac-address | D7: 00:0a:35:00:00:0a
B10: 2. Processing element
C12: name | D12: ru-pe.0
C13: ODU mac-address | D13: 00:11:22:33:44:55
B16: 3. PDSCH
C18: end-point | G18: link | K18: array-carrier
C19: name | D19: scs | E19: number-of-prb | F19: eaxc-id | G19: name | H19: processing-element | I19: rx-array-carrier | J19: low-level-rx-endpoint | K19: name | L19: Center-FREQ | M19: Channel-BW | N19: type | O19: gain
A20: ON | B20: C0 | C20: llte_0_0_0_1_0_0 | D20: KHZ_15 | E20: 106 | F20: 2 | G20: llte_0_0_0_1_0_0 | H20: ru-pe.0 | I20: tac_0_0_0_1 | J20: llte_0_0_0_1_0_0 | K20: tac_0_0_0_1 | L20: 3415 | M20: 10000000 | N20: NR | O20: 7 | P20: 2
A21: ON | B21: C1 | C21: llte_0_0_1_1_0_0 | D21: KHZ_15 | E21: 106 | F21: 3 | G21: llte_0_0_1_1_0_0 | H21: ru-pe.0 | I21: tac_0_0_1_1 | J21: llte_0_0_1_1_0_0 | K21: tac_0_0_1_1 | L21: 3445 | M21: 10000000 | N21: NR | O21: 7 | P21: 3
A22: OFF | B22: C2 | C22: llte_0_0_0_2_0_0 | D22: KHZ_15 | E22: 106 | F22: 4 | G22: llte_0_0_0_2_0_0 | H22: ru-pe.0 | I22: tac_0_0_0_2 | J22: llte_0_0_0_2_0_0 | K22: tac_0_0_0_2 | L22: 3415 | M22: 10000000 | N22: NR | O22: 7 | P22: 4
A23: OFF | B23: C3 | C23: llte_0_0_1_2_0_0 | D23: KHZ_15 | E23: 106 | F23: 5 | G23: llte_0_0_1_2_0_0 | H23: ru-pe.0 | I23: tac_0_0_1_2 | J23: llte_0_0_1_2_0_0 | K23: tac_0_0_1_2 | L23: 3445 | M23: 10000000 | N23: NR | O23: 7 | P23: 5
A24: OFF | B24: C4 | C24: llte_0_0_0_3_0_0 | D24: KHZ_15 | E24: 106 | F24: 6 | G24: llte_0_0_0_3_0_0 | H24: ru-pe.0 | I24: tac_0_0_0_3 | J24: llte_0_0_0_3_0_0 | K24: tac_0_0_0_3 | L24: 3415 | M24: 10000000 | N24: NR | O24: 7 | P24: 6
A25: OFF | B25: C5 | C25: llte_0_0_1_3_0_0 | D25: KHZ_15 | E25: 106 | F25: 7 | G25: llte_0_0_1_3_0_0 | H25: ru-pe.0 | I25: tac_0_0_1_3 | J25: llte_0_0_1_3_0_0 | K25: tac_0_0_1_3 | L25: 3445 | M25: 10000000 | N25: NR | O25: 7 | P25: 7
A26: OFF | B26: C6 | C26: llte_0_0_0_4_0_0 | D26: KHZ_15 | E26: 106 | F26: 8 | G26: llte_0_0_0_4_0_0 | H26: ru-pe.0 | I26: tac_0_0_0_4 | J26: llte_0_0_0_4_0_0 | K26: tac_0_0_0_4 | L26: 3415 | M26: 10000000 | N26: NR | O26: 7 | P26: 8
A27: OFF | B27: C7 | C27: llte_0_0_1_4_0_0 | D27: KHZ_15 | E27: 106 | F27: 9 | G27: llte_0_0_1_4_0_0 | H27: ru-pe.0 | I27: tac_0_0_1_4 | J27: llte_0_0_1_4_0_0 | K27: tac_0_0_1_4 | L27: 3445 | M27: 10000000 | N27: NR | O27: 7 | P27: 9
B30: 4. PUSCH
C32: end-point | H32: link | L32: array-carrier
C33: name | D33: scs | E33: number-of-prb | F33: ul-fft-sampling-offset | G33: eaxc-id | H33: name | I33: processing-element | J33: rx-array-carrier | K33: low-level-rx-endpoint | L33: name | M33: Center-FREQ | N33: Channel-BW | O33: type | P33: n-ta-offset
B34: C0 | C34: llre_0_0_0_1_0_0 | D34: KHZ_15 | E34: 106 | F34: 0 | G34: 18 | H34: llre_0_0_0_1_0_0 | I34: ru-pe.0 | J34: rac_0_0_0_1 | K34: llre_0_0_0_1_0_0 | L34: rac_0_0_0_1 | M34: 3415 | N34: 10000000 | O34: NR | P34: 25600 | Q34: 12
B35: C1 | C35: llre_0_0_1_1_0_0 | D35: KHZ_15 | E35: 106 | F35: 0 | G35: 19 | H35: llre_0_0_1_1_0_0 | I35: ru-pe.0 | J35: rac_0_0_1_1 | K35: llre_0_0_1_1_0_0 | L35: rac_0_0_1_1 | M35: 3445 | N35: 10000000 | O35: NR | P35: 25600 | Q35: 13
B36: C2 | C36: llre_0_0_0_2_0_0 | D36: KHZ_15 | E36: 106 | F36: 0 | G36: 20 | H36: llre_0_0_0_2_0_0 | I36: ru-pe.0 | J36: rac_0_0_0_2 | K36: llre_0_0_0_2_0_0 | L36: rac_0_0_0_2 | M36: 3415 | N36: 10000000 | O36: NR | P36: 25600 | Q36: 14
B37: C3 | C37: llre_0_0_1_2_0_0 | D37: KHZ_15 | E37: 106 | F37: 0 | G37: 21 | H37: llre_0_0_1_2_0_0 | I37: ru-pe.0 | J37: rac_0_0_1_2 | K37: llre_0_0_1_2_0_0 | L37: rac_0_0_1_2 | M37: 3445 | N37: 10000000 | O37: NR | P37: 25600 | Q37: 15
B38: C4 | C38: llre_0_0_0_3_0_0 | D38: KHZ_15 | E38: 106 | F38: 0 | G38: 22 | H38: llre_0_0_0_3_0_0 | I38: ru-pe.0 | J38: rac_0_0_0_3 | K38: llre_0_0_0_3_0_0 | L38: rac_0_0_0_3 | M38: 3415 | N38: 10000000 | O38: NR | P38: 25600 | Q38: 16
B39: C5 | C39: llre_0_0_1_3_0_0 | D39: KHZ_15 | E39: 106 | F39: 0 | G39: 23 | H39: llre_0_0_1_3_0_0 | I39: ru-pe.0 | J39: rac_0_0_1_3 | K39: llre_0_0_1_3_0_0 | L39: rac_0_0_1_3 | M39: 3445 | N39: 10000000 | O39: NR | P39: 25600 | Q39: 17
B40: C6 | C40: llre_0_0_0_4_0_0 | D40: KHZ_15 | E40: 106 | F40: 0 | G40: 24 | H40: llre_0_0_0_4_0_0 | I40: ru-pe.0 | J40: rac_0_0_0_4 | K40: llre_0_0_0_4_0_0 | L40: rac_0_0_0_4 | M40: 3415 | N40: 10000000 | O40: NR | P40: 25600 | Q40: 18
B41: C7 | C41: llre_0_0_1_4_0_0 | D41: KHZ_15 | E41: 106 | F41: 0 | G41: 25 | H41: llre_0_0_1_4_0_0 | I41: ru-pe.0 | J41: rac_0_0_1_4 | K41: llre_0_0_1_4_0_0 | L41: rac_0_0_1_4 | M41: 3445 | N41: 10000000 | O41: NR | P41: 25600 | Q41: 19
B44: 5. PRACH
C46: end-point | H46: link
C47: name | D47: scs | E47: number-of-prb | F47: ul-fft-sampling-offset | G47: eaxc-id | H47: name | I47: processing-element | J47: rx-array-carrier | K47: low-level-rx-endpoint
B48: C0 | C48: llre_0_0_0_1_0_0 | D48: KHZ_15 | E48: 106 | F48: 0 | G48: 34 | H48: llre_0_0_0_1_0_0 | I48: ru-pe.0 | J48: rac_0_0_0_1 | K48: llre_0_0_0_1_0_0 | L48: 22
B49: C1 | C49: llre_0_0_1_1_1_0 | D49: KHZ_15 | E49: 106 | F49: 0 | G49: 35 | H49: llre_0_0_1_1_1_0 | I49: ru-pe.0 | J49: rac_0_0_1_1 | K49: llre_0_0_1_1_1_0 | L49: 23
B50: C2 | C50: llre_0_0_0_2_0_0 | D50: KHZ_15 | E50: 106 | F50: 0 | G50: 36 | H50: llre_0_0_0_2_0_0 | I50: ru-pe.0 | J50: rac_0_0_0_2 | K50: llre_0_0_0_2_0_0 | L50: 24
B51: C3 | C51: llre_0_0_1_2_1_0 | D51: KHZ_15 | E51: 106 | F51: 0 | G51: 37 | H51: llre_0_0_1_2_1_0 | I51: ru-pe.0 | J51: rac_0_0_1_2 | K51: llre_0_0_1_2_1_0 | L51: 25
B52: C4 | C52: llre_0_0_0_3_0_0 | D52: KHZ_15 | E52: 106 | F52: 0 | G52: 38 | H52: llre_0_0_0_3_0_0 | I52: ru-pe.0 | J52: rac_0_0_0_3 | K52: llre_0_0_0_3_0_0 | L52: 26
B53: C5 | C53: llre_0_0_1_3_1_0 | D53: KHZ_15 | E53: 106 | F53: 0 | G53: 39 | H53: llre_0_0_1_3_1_0 | I53: ru-pe.0 | J53: rac_0_0_1_3 | K53: llre_0_0_1_3_1_0 | L53: 27
B54: C6 | C54: llre_0_0_0_4_0_0 | D54: KHZ_15 | E54: 106 | F54: 0 | G54: 40 | H54: llre_0_0_0_4_0_0 | I54: ru-pe.0 | J54: rac_0_0_0_4 | K54: llre_0_0_0_4_0_0 | L54: 28
...

Sheet CUplane-interface
A1: <?xml version="1.0" encoding="UTF-8"?>
A2: <rpc xmlns="urn:ietf:params:xml:ns:netconf:base:1.0" message-id="1">
A3: <edit-config>
A4: <target>
A5: <running/>
A6: </target>
A7: <default-operation>merge</default-operation>
A8: <config>
A9: <interfaces xmlns="urn:ietf:params:xml:ns:yang:ietf-interfaces">
A10: <interface>
A11: =" <name>"&'Control-Sheet'!D4&"</name>"
A12: <type xmlns:ianaift="urn:ietf:params:xml:ns:yang:iana-if-type">ianaift:l2vlan</type>
A13: =" <base-interface xmlns="&CHAR(34)&"urn:o-ran:interfaces:1.0"&CHAR(34)&">"&'Control-Sheet'!D5&"</base-interface>"
A14: =" <vlan-id xmlns="&CHAR(34)&"urn:o-ran:interfaces:1.0"&CHAR(34)&">"&'Control-Sheet'!D6&"</vlan-id>"
A15: =" <mac-address xmlns="&CHAR(34)&"urn:o-ran:interfaces:1.0"&CHAR(34)&">"&'Control-Sheet'!D7&"</mac-address>"
A16: <port-reference xmlns="urn:o-ran:interfaces:1.0">
A17: <port-number>0</port-number>
A18: </port-reference>
A19: </interface>
A20: </interfaces>
A21: </config>
A22: </edit-config>
A23: </rpc>

Sheet Processing-element
A1: <?xml version="1.0" encoding="UTF-8"?>
A2: <rpc xmlns="urn:ietf:params:xml:ns:netconf:base:1.0" message-id="1">
A3: <edit-config>
A4: <target>
A5: <running/>
A6: </target>
A7: <default-operation>merge</default-operation>
A8: <config>
A9: <processing-elements xmlns="urn:o-ran:processing-element:1.0">
A10: <transport-session-type>ETH-INTERFACE</transport-session-type>
A11: <ru-elements>
A12: =" <name>"&'Control-Sheet'!D12&"</name>"
A13: <transport-flow>
A14: =" <interface-name>"&'Control-Sheet'!D4&"</interface-name>"
A15: <eth-flow>
A16: =" <ru-mac-address>"&'Control-Sheet'!D7&"</ru-mac-address>"
A17: =" <vlan-id>"&'Control-Sheet'!D6&"</vlan-id>"
A18: =" <o-du-mac-address>"&'Control-Sheet'!D13&"</o-du-mac-address>"
A19: </eth-flow>
A20: </transport-flow>
A21: </ru-elements>
A22: </processing-elements>
A23: </config>
A24: </edit-config>
A25: </rpc>

Sheet PDSCH
A1: <?xml version="1.0" encoding="UTF-8"?>
A2: <rpc xmlns="urn:ietf:params:xml:ns:netconf:base:1.0" message-id="1">
A3: <edit-config>
A4: <target>
A5: <running/>
A6: </target>
A7: <default-operation>merge</default-operation>
A8: <config>
A9: <user-plane-configuration xmlns="urn:o-ran:uplane-conf:1.0">
A12: <low-level-tx-endpoints>
A13: =" <name>"&'Control-Sheet'!$C20&"</name>"
A14: <compression>
A15: <compression-type>STATIC</compression-type>
A16: <iq-bitwidth>16</iq-bitwidth>
A17: </compression>
A18: <frame-structure>160</frame-structure>
A19: <cp-type>NORMAL</cp-type>
A20: <cp-length>160</cp-length>
A21: <cp-length-other>144</cp-length-other>
A22: <offset-to-absolute-frequency-center>0</offset-to-absolute-frequency-center>
A23: <number-of-prb-per-scs>
A24: =" <scs>"&'Control-Sheet'!$D20&"</scs>"
A25: =" <number-of-prb>"&'Control-Sheet'!$E20&"</number-of-prb>"
A26: </number-of-prb-per-scs>
A27: <e-axcid>
A28: <o-du-port-bitmask>49152</o-du-port-bitmask>
A29: <band-sector-bitmask>12288</band-sector-bitmask>
A30: <ccid-bitmask>3840</ccid-bitmask>
A31: <ru-port-bitmask>255</ru-port-bitmask>
A32: =" <eaxc-id>"&'Control-Sheet'!$F20&"</eaxc-id>"
A33: </e-axcid>
A34: </low-level-tx-endpoints>
A35: <tx-array-carriers>
A36: =" <name>"&'Control-Sheet'!$K20&"</name>"
A37: <absolute-frequency-center>0</absolute-frequency-center>
A38: =" <center-of-channel-bandwidth>"&'Control-Sheet'!$L20*10^6&"</center-of-channel-bandwidth>"
A39: =" <channel-bandwidth>"&'Control-Sheet'!$M20*10^6&"</channel-bandwidth>"
A40: <active>INACTIVE</active>
A41: =" <type>"&'Control-Sheet'!$N20&"</type>"
A42: <downlink-radio-frame-offset>0</downlink-radio-frame-offset>
...

Sheet PUSCH
A1: <?xml version="1.0" encoding="UTF-8"?>
A2: <rpc xmlns="urn:ietf:params:xml:ns:netconf:base:1.0" message-id="1">
A3: <edit-config>
A4: <target>
A5: <running/>
A6: </target>
A7: <default-operation>merge</default-operation>
A8: <config>
A9: <user-plane-configuration xmlns="urn:o-ran:uplane-conf:1.0">
A12: <low-level-rx-endpoints>
A13: =" <name>"&'Control-Sheet'!$C34&"</name>"
A14: <compression>
A15: <compression-type>STATIC</compression-type>
A16: <iq-bitwidth>16</iq-bitwidth>
A17: </compression>
A18: <frame-structure>160</frame-structure>
A19: <cp-type>NORMAL</cp-type>
A20: <cp-length>160</cp-length>
A21: <cp-length-other>144</cp-length-other>
A22: <offset-to-absolute-frequency-center>0</offset-to-absolute-frequency-center>
A23: <number-of-prb-per-scs>
A24: =" <scs>"&'Control-Sheet'!$D34&"</scs>"
A25: =" <number-of-prb>"&'Control-Sheet'!$E34&"</number-of-prb>"
A26: </number-of-prb-per-scs>
A27: <ul-fft-sampling-offsets>
A28: =" <scs>"&'Control-Sheet'!$D34&"</scs>"
A29: =" <ul-fft-sampling-offset>"&'Control-Sheet'!$F34&"</ul-fft-sampling-offset>"
A30: </ul-fft-sampling-offsets>
A31: <e-axcid>
A32: <o-du-port-bitmask>49152</o-du-port-bitmask>
A33: <band-sector-bitmask>12288</band-sector-bitmask>
A34: <ccid-bitmask>3840</ccid-bitmask>
A35: <ru-port-bitmask>255</ru-port-bitmask>
A36: =" <eaxc-id>"&'Control-Sheet'!$G34&"</eaxc-id>"
A37: </e-axcid>
A38: </low-level-rx-endpoints>
A39: <rx-array-carriers>
A40: =" <name>"&'Control-Sheet'!$L34&"</name>"
A41: <absolute-frequency-center>0</absolute-frequency-center>
A42: =" <center-of-channel-bandwidth>"&'Control-Sheet'!$M34*10^6&"</center-of-channel-bandwidth>"
...

Sheet PRACH
A1: <?xml version="1.0" encoding="UTF-8"?>
A2: <rpc xmlns="urn:ietf:params:xml:ns:netconf:base:1.0" message-id="1">
A3: <edit-config>
A4: <target>
A5: <running/>
A6: </target>
A7: <default-operation>merge</default-operation>
A8: <config>
A9: <user-plane-configuration xmlns="urn:o-ran:uplane-conf:1.0">
A12: <low-level-rx-endpoints>
A13: =" <name>"&'Control-Sheet'!$C48&"</name>"
A14: <compression>
A15: <compression-type>STATIC</compression-type>
A16: <iq-bitwidth>16</iq-bitwidth>
A17: </compression>
A18: <frame-structure>160</frame-structure>
A19: <cp-type>NORMAL</cp-type>
A20: <cp-length>160</cp-length>
A21: <cp-length-other>144</cp-length-other>
A22: <offset-to-absolute-frequency-center>0</offset-to-absolute-frequency-center>
A23: <number-of-prb-per-scs>
A24: =" <scs>"&'Control-Sheet'!$D48&"</scs>"
A25: =" <number-of-prb>"&'Control-Sheet'!$E48&"</number-of-prb>"
A26: </number-of-prb-per-scs>
A27: <ul-fft-sampling-offsets>
A28: =" <scs>"&'Control-Sheet'!$D48&"</scs>"
A29: =" <ul-fft-sampling-offset>"&'Control-Sheet'!$F48&"</ul-fft-sampling-offset>"
A30: </ul-fft-sampling-offsets>
A31: <e-axcid>
A32: <o-du-port-bitmask>49152</o-du-port-bitmask>
A33: <band-sector-bitmask>12288</band-sector-bitmask>
A34: <ccid-bitmask>3840</ccid-bitmask>
A35: <ru-port-bitmask>255</ru-port-bitmask>
A36: =" <eaxc-id>"&'Control-Sheet'!$G48&"</eaxc-id>"
A37: </e-axcid>
A38: </low-level-rx-endpoints>
A39: <low-level-rx-links>
A40: =" <name>"&'Control-Sheet'!$H48&"</name>"
A41: =" <processing-element>"&'Control-Sheet'!$I48&"</processing-element>"
A42: =" <rx-array-carrier>"&'Control-Sheet'!$J48&"</rx-array-carrier>"
...

Sheet ACTIVE
A1: <rpc message-id="30" xmlns="urn:ietf:params:xml:ns:netconf:base:1.0">
A2: <edit-config>
A3: <target>
A4: <running/>
A5: </target>
A6: <config>
A7: <user-plane-configuration xmlns="urn:o-ran:uplane-conf:1.0">
A8: <tx-array-carriers>
A9: =" <name>"&'Control-Sheet'!$K20&"</name>"
A10: <active>ACTIVE</active>
A11: </tx-array-carriers>
A12: <tx-array-carriers>
A13: =" <name>"&'Control-Sheet'!$K21&"</name>"
A14: <active>ACTIVE</active>
A15: </tx-array-carriers>
A16: <tx-array-carriers>
A17: =" <name>"&'Control-Sheet'!$K22&"</name>"
A18: <active>ACTIVE</active>
A19: </tx-array-carriers>
A20: <tx-array-carriers>
A21: =" <name>"&'Control-Sheet'!$K23&"</name>"
A22: <active>ACTIVE</active>
A23: </tx-array-carriers>
A24: <tx-array-carriers>
A25: =" <name>"&'Control-Sheet'!$K24&"</name>"
A26: <active>ACTIVE</active>
A27: </tx-array-carriers>
A28: <tx-array-carriers>
A29: =" <name>"&'Control-Sheet'!$K25&"</name>"
A30: <active>ACTIVE</active>
A31: </tx-array-carriers>
A32: <tx-array-carriers>
A33: =" <name>"&'Control-Sheet'!$K26&"</name>"
A34: <active>ACTIVE</active>
A35: </tx-array-carriers>
A36: <tx-array-carriers>
A37: =" <name>"&'Control-Sheet'!$K27&"</name>"
A38: <active>ACTIVE</active>
A39: </tx-array-carriers>
A42: <rx-array-carriers>
...
